2025-01-17 20:12:13,199 - INFO - [pid 53683] Worker Worker(salt=7749433973, workers=1, host=LAPTOP-2FUAA63D, username=root, pid=53683) done      ExtractMarketingData()
2025-01-17 20:12:13,199 - DEBUG - 1 running tasks, waiting for next task to finish
2025-01-17 20:12:13,200 - INFO - Informed scheduler that task   ExtractMarketingData__99914b932b   has status   DONE
2025-01-17 20:12:13,200 - DEBUG - Asking scheduler for work...
2025-01-17 20:12:13,200 - DEBUG - Pending tasks: 7
2025-01-17 20:12:13,201 - INFO - [pid 53683] Worker Worker(salt=7749433973, workers=1, host=LAPTOP-2FUAA63D, username=root, pid=53683) running   ExtractSalesData()
2025-01-17 20:12:13,274 - ERROR - [pid 53683] Worker Worker(salt=7749433973, workers=1, host=LAPTOP-2FUAA63D, username=root, pid=53683) failed    ExtractSalesData()
Traceback (most recent call last):
  File "/usr/local/lib/python3.10/dist-packages/sqlalchemy/engine/base.py", line 146, in __init__
    self._dbapi_connection = engine.raw_connection()
  File "/usr/local/lib/python3.10/dist-packages/sqlalchemy/engine/base.py", line 3298, in raw_connection
    return self.pool.connect()
  File "/usr/local/lib/python3.10/dist-packages/sqlalchemy/pool/base.py", line 449, in connect
    return _ConnectionFairy._checkout(self)
  File "/usr/local/lib/python3.10/dist-packages/sqlalchemy/pool/base.py", line 1263, in _checkout
    fairy = _ConnectionRecord.checkout(pool)
  File "/usr/local/lib/python3.10/dist-packages/sqlalchemy/pool/base.py", line 712, in checkout
    rec = pool._do_get()
  File "/usr/local/lib/python3.10/dist-packages/sqlalchemy/pool/impl.py", line 179, in _do_get
    with util.safe_reraise():
  File "/usr/local/lib/python3.10/dist-packages/sqlalchemy/util/langhelpers.py", line 146, in __exit__
    raise exc_value.with_traceback(exc_tb)
  File "/usr/local/lib/python3.10/dist-packages/sqlalchemy/pool/impl.py", line 177, in _do_get
    return self._create_connection()
  File "/usr/local/lib/python3.10/dist-packages/sqlalchemy/pool/base.py", line 390, in _create_connection
    return _ConnectionRecord(self)
  File "/usr/local/lib/python3.10/dist-packages/sqlalchemy/pool/base.py", line 674, in __init__
    self.__connect()
  File "/usr/local/lib/python3.10/dist-packages/sqlalchemy/pool/base.py", line 900, in __connect
    with util.safe_reraise():
  File "/usr/local/lib/python3.10/dist-packages/sqlalchemy/util/langhelpers.py", line 146, in __exit__
    raise exc_value.with_traceback(exc_tb)
  File "/usr/local/lib/python3.10/dist-packages/sqlalchemy/pool/base.py", line 896, in __connect
    self.dbapi_connection = connection = pool._invoke_creator(self)
  File "/usr/local/lib/python3.10/dist-packages/sqlalchemy/engine/create.py", line 646, in connect
    return dialect.connect(*cargs, **cparams)
  File "/usr/local/lib/python3.10/dist-packages/sqlalchemy/engine/default.py", line 622, in connect
    return self.loaded_dbapi.connect(*cargs, **cparams)
  File "/usr/local/lib/python3.10/dist-packages/psycopg2/__init__.py", line 122, in connect
    conn = _connect(dsn, connection_factory=connection_factory, **kwasync)
psycopg2.OperationalError: connection to server at "localhost" (127.0.0.1), port 5436 failed: FATAL:  password authentication failed for user "postgres"


The above exception was the direct cause of the following exception:

Traceback (most recent call last):
  File "/usr/local/lib/python3.10/dist-packages/luigi/worker.py", line 210, in run
    new_deps = self._run_get_new_deps()
  File "/usr/local/lib/python3.10/dist-packages/luigi/worker.py", line 138, in _run_get_new_deps
    task_gen = self.task.run()
  File "/root/etl_final_task/etl_luigi.py", line 87, in run
    extract_sales_data = pd.read_sql(sql=query, con=engine)
  File "/usr/local/lib/python3.10/dist-packages/pandas/io/sql.py", line 704, in read_sql
    with pandasSQL_builder(con) as pandas_sql:
  File "/usr/local/lib/python3.10/dist-packages/pandas/io/sql.py", line 906, in pandasSQL_builder
    return SQLDatabase(con, schema, need_transaction)
  File "/usr/local/lib/python3.10/dist-packages/pandas/io/sql.py", line 1636, in __init__
    con = self.exit_stack.enter_context(con.connect())
  File "/usr/local/lib/python3.10/dist-packages/sqlalchemy/engine/base.py", line 3274, in connect
    return self._connection_cls(self)
  File "/usr/local/lib/python3.10/dist-packages/sqlalchemy/engine/base.py", line 148, in __init__
    Connection._handle_dbapi_exception_noconnection(
  File "/usr/local/lib/python3.10/dist-packages/sqlalchemy/engine/base.py", line 2439, in _handle_dbapi_exception_noconnection
    raise sqlalchemy_exception.with_traceback(exc_info[2]) from e
  File "/usr/local/lib/python3.10/dist-packages/sqlalchemy/engine/base.py", line 146, in __init__
    self._dbapi_connection = engine.raw_connection()
  File "/usr/local/lib/python3.10/dist-packages/sqlalchemy/engine/base.py", line 3298, in raw_connection
    return self.pool.connect()
  File "/usr/local/lib/python3.10/dist-packages/sqlalchemy/pool/base.py", line 449, in connect
    return _ConnectionFairy._checkout(self)
  File "/usr/local/lib/python3.10/dist-packages/sqlalchemy/pool/base.py", line 1263, in _checkout
    fairy = _ConnectionRecord.checkout(pool)
  File "/usr/local/lib/python3.10/dist-packages/sqlalchemy/pool/base.py", line 712, in checkout
    rec = pool._do_get()
  File "/usr/local/lib/python3.10/dist-packages/sqlalchemy/pool/impl.py", line 179, in _do_get
    with util.safe_reraise():
  File "/usr/local/lib/python3.10/dist-packages/sqlalchemy/util/langhelpers.py", line 146, in __exit__
    raise exc_value.with_traceback(exc_tb)
  File "/usr/local/lib/python3.10/dist-packages/sqlalchemy/pool/impl.py", line 177, in _do_get
    return self._create_connection()
  File "/usr/local/lib/python3.10/dist-packages/sqlalchemy/pool/base.py", line 390, in _create_connection
    return _ConnectionRecord(self)
  File "/usr/local/lib/python3.10/dist-packages/sqlalchemy/pool/base.py", line 674, in __init__
    self.__connect()
  File "/usr/local/lib/python3.10/dist-packages/sqlalchemy/pool/base.py", line 900, in __connect
    with util.safe_reraise():
  File "/usr/local/lib/python3.10/dist-packages/sqlalchemy/util/langhelpers.py", line 146, in __exit__
    raise exc_value.with_traceback(exc_tb)
  File "/usr/local/lib/python3.10/dist-packages/sqlalchemy/pool/base.py", line 896, in __connect
    self.dbapi_connection = connection = pool._invoke_creator(self)
  File "/usr/local/lib/python3.10/dist-packages/sqlalchemy/engine/create.py", line 646, in connect
    return dialect.connect(*cargs, **cparams)
  File "/usr/local/lib/python3.10/dist-packages/sqlalchemy/engine/default.py", line 622, in connect
    return self.loaded_dbapi.connect(*cargs, **cparams)
  File "/usr/local/lib/python3.10/dist-packages/psycopg2/__init__.py", line 122, in connect
    conn = _connect(dsn, connection_factory=connection_factory, **kwasync)
sqlalchemy.exc.OperationalError: (psycopg2.OperationalError) connection to server at "localhost" (127.0.0.1), port 5436 failed: FATAL:  password authentication failed for user "postgres"

(Background on this error at: https://sqlalche.me/e/20/e3q8)
2025-01-17 20:12:13,279 - DEBUG - 1 running tasks, waiting for next task to finish
2025-01-17 20:12:13,282 - INFO - Informed scheduler that task   ExtractSalesData__99914b932b   has status   FAILED
2025-01-17 20:12:13,282 - DEBUG - Asking scheduler for work...
2025-01-17 20:12:13,283 - DEBUG - Pending tasks: 7
2025-01-17 20:12:13,283 - INFO - [pid 53683] Worker Worker(salt=7749433973, workers=1, host=LAPTOP-2FUAA63D, username=root, pid=53683) running   ExtractNewsData()
2025-01-17 20:14:20,574 - INFO - [pid 53683] Worker Worker(salt=7749433973, workers=1, host=LAPTOP-2FUAA63D, username=root, pid=53683) done      ExtractNewsData()
2025-01-17 20:14:20,574 - DEBUG - 1 running tasks, waiting for next task to finish
2025-01-17 20:14:20,575 - INFO - Informed scheduler that task   ExtractNewsData__99914b932b   has status   DONE
2025-01-17 20:14:20,575 - DEBUG - Asking scheduler for work...
2025-01-17 20:14:20,575 - DEBUG - Pending tasks: 6
2025-01-17 20:14:20,575 - INFO - [pid 53683] Worker Worker(salt=7749433973, workers=1, host=LAPTOP-2FUAA63D, username=root, pid=53683) running   TransformMarketingData()
2025-01-17 20:14:20,576 - ERROR - [pid 53683] Worker Worker(salt=7749433973, workers=1, host=LAPTOP-2FUAA63D, username=root, pid=53683) failed    TransformMarketingData()
Traceback (most recent call last):
  File "/usr/local/lib/python3.10/dist-packages/luigi/worker.py", line 210, in run
    new_deps = self._run_get_new_deps()
  File "/usr/local/lib/python3.10/dist-packages/luigi/worker.py", line 138, in _run_get_new_deps
    task_gen = self.task.run()
  File "/root/etl_final_task/etl_luigi.py", line 284, in run
    marketing_data = pd.read_csv(self.input()[0].path)
TypeError: 'LocalTarget' object is not subscriptable
2025-01-17 20:14:20,576 - DEBUG - 1 running tasks, waiting for next task to finish
2025-01-17 20:14:20,578 - INFO - Informed scheduler that task   TransformMarketingData__99914b932b   has status   FAILED
2025-01-17 20:14:20,578 - DEBUG - Asking scheduler for work...
2025-01-17 20:14:20,578 - DEBUG - Pending tasks: 6
2025-01-17 20:14:20,578 - INFO - [pid 53683] Worker Worker(salt=7749433973, workers=1, host=LAPTOP-2FUAA63D, username=root, pid=53683) running   TransformNewsData()
2025-01-17 20:14:20,579 - ERROR - [pid 53683] Worker Worker(salt=7749433973, workers=1, host=LAPTOP-2FUAA63D, username=root, pid=53683) failed    TransformNewsData()
Traceback (most recent call last):
  File "/usr/local/lib/python3.10/dist-packages/luigi/worker.py", line 210, in run
    new_deps = self._run_get_new_deps()
  File "/usr/local/lib/python3.10/dist-packages/luigi/worker.py", line 138, in _run_get_new_deps
    task_gen = self.task.run()
  File "/root/etl_final_task/etl_luigi.py", line 600, in run
    news_data = pd.read_csv(self.input()[0].path)
TypeError: 'LocalTarget' object is not subscriptable
2025-01-17 20:14:20,579 - DEBUG - 1 running tasks, waiting for next task to finish
2025-01-17 20:14:20,580 - INFO - Informed scheduler that task   TransformNewsData__99914b932b   has status   FAILED
2025-01-17 20:14:20,581 - DEBUG - Asking scheduler for work...
2025-01-17 20:14:20,581 - DEBUG - Done
2025-01-17 20:14:20,581 - DEBUG - There are no more tasks to run at this time
2025-01-17 20:14:20,581 - DEBUG - There are 6 pending tasks possibly being run by other workers
2025-01-17 20:14:20,581 - DEBUG - There are 6 pending tasks unique to this worker
2025-01-17 20:14:20,581 - DEBUG - There are 6 pending tasks last scheduled by this worker
2025-01-17 20:14:20,581 - INFO - Worker Worker(salt=7749433973, workers=1, host=LAPTOP-2FUAA63D, username=root, pid=53683) was stopped. Shutting down Keep-Alive thread
2025-01-17 20:14:20,583 - INFO - 
===== Luigi Execution Summary =====

Scheduled 8 tasks of which:
* 2 ran successfully:
    - 1 ExtractMarketingData()
    - 1 ExtractNewsData()
* 3 failed:
    - 1 ExtractSalesData()
    - 1 TransformMarketingData()
    - 1 TransformNewsData()
* 3 were left pending, among these:
    * 3 had failed dependencies:
        - 1 LoadData()
        - 1 TransformSalesData()
        - 1 ValidateData()

This progress looks :( because there were failed tasks

===== Luigi Execution Summary =====

2025-01-17 20:33:49,148 - ERROR - [pid 63092] Worker Worker(salt=7320377462, workers=1, host=LAPTOP-2FUAA63D, username=root, pid=63092) failed    ExtractSalesData()
Traceback (most recent call last):
  File "/usr/local/lib/python3.10/dist-packages/sqlalchemy/engine/base.py", line 146, in __init__
    self._dbapi_connection = engine.raw_connection()
  File "/usr/local/lib/python3.10/dist-packages/sqlalchemy/engine/base.py", line 3298, in raw_connection
    return self.pool.connect()
  File "/usr/local/lib/python3.10/dist-packages/sqlalchemy/pool/base.py", line 449, in connect
    return _ConnectionFairy._checkout(self)
  File "/usr/local/lib/python3.10/dist-packages/sqlalchemy/pool/base.py", line 1263, in _checkout
    fairy = _ConnectionRecord.checkout(pool)
  File "/usr/local/lib/python3.10/dist-packages/sqlalchemy/pool/base.py", line 712, in checkout
    rec = pool._do_get()
  File "/usr/local/lib/python3.10/dist-packages/sqlalchemy/pool/impl.py", line 179, in _do_get
    with util.safe_reraise():
  File "/usr/local/lib/python3.10/dist-packages/sqlalchemy/util/langhelpers.py", line 146, in __exit__
    raise exc_value.with_traceback(exc_tb)
  File "/usr/local/lib/python3.10/dist-packages/sqlalchemy/pool/impl.py", line 177, in _do_get
    return self._create_connection()
  File "/usr/local/lib/python3.10/dist-packages/sqlalchemy/pool/base.py", line 390, in _create_connection
    return _ConnectionRecord(self)
  File "/usr/local/lib/python3.10/dist-packages/sqlalchemy/pool/base.py", line 674, in __init__
    self.__connect()
  File "/usr/local/lib/python3.10/dist-packages/sqlalchemy/pool/base.py", line 900, in __connect
    with util.safe_reraise():
  File "/usr/local/lib/python3.10/dist-packages/sqlalchemy/util/langhelpers.py", line 146, in __exit__
    raise exc_value.with_traceback(exc_tb)
  File "/usr/local/lib/python3.10/dist-packages/sqlalchemy/pool/base.py", line 896, in __connect
    self.dbapi_connection = connection = pool._invoke_creator(self)
  File "/usr/local/lib/python3.10/dist-packages/sqlalchemy/engine/create.py", line 646, in connect
    return dialect.connect(*cargs, **cparams)
  File "/usr/local/lib/python3.10/dist-packages/sqlalchemy/engine/default.py", line 622, in connect
    return self.loaded_dbapi.connect(*cargs, **cparams)
  File "/usr/local/lib/python3.10/dist-packages/psycopg2/__init__.py", line 122, in connect
    conn = _connect(dsn, connection_factory=connection_factory, **kwasync)
psycopg2.OperationalError: connection to server at "localhost" (127.0.0.1), port 5436 failed: FATAL:  password authentication failed for user "postgres"


The above exception was the direct cause of the following exception:

Traceback (most recent call last):
  File "/usr/local/lib/python3.10/dist-packages/luigi/worker.py", line 210, in run
    new_deps = self._run_get_new_deps()
  File "/usr/local/lib/python3.10/dist-packages/luigi/worker.py", line 138, in _run_get_new_deps
    task_gen = self.task.run()
  File "/root/etl_final_task/etl_luigi.py", line 87, in run
    extract_sales_data = pd.read_sql(sql=query, con=engine)
  File "/usr/local/lib/python3.10/dist-packages/pandas/io/sql.py", line 704, in read_sql
    with pandasSQL_builder(con) as pandas_sql:
  File "/usr/local/lib/python3.10/dist-packages/pandas/io/sql.py", line 906, in pandasSQL_builder
    return SQLDatabase(con, schema, need_transaction)
  File "/usr/local/lib/python3.10/dist-packages/pandas/io/sql.py", line 1636, in __init__
    con = self.exit_stack.enter_context(con.connect())
  File "/usr/local/lib/python3.10/dist-packages/sqlalchemy/engine/base.py", line 3274, in connect
    return self._connection_cls(self)
  File "/usr/local/lib/python3.10/dist-packages/sqlalchemy/engine/base.py", line 148, in __init__
    Connection._handle_dbapi_exception_noconnection(
  File "/usr/local/lib/python3.10/dist-packages/sqlalchemy/engine/base.py", line 2439, in _handle_dbapi_exception_noconnection
    raise sqlalchemy_exception.with_traceback(exc_info[2]) from e
  File "/usr/local/lib/python3.10/dist-packages/sqlalchemy/engine/base.py", line 146, in __init__
    self._dbapi_connection = engine.raw_connection()
  File "/usr/local/lib/python3.10/dist-packages/sqlalchemy/engine/base.py", line 3298, in raw_connection
    return self.pool.connect()
  File "/usr/local/lib/python3.10/dist-packages/sqlalchemy/pool/base.py", line 449, in connect
    return _ConnectionFairy._checkout(self)
  File "/usr/local/lib/python3.10/dist-packages/sqlalchemy/pool/base.py", line 1263, in _checkout
    fairy = _ConnectionRecord.checkout(pool)
  File "/usr/local/lib/python3.10/dist-packages/sqlalchemy/pool/base.py", line 712, in checkout
    rec = pool._do_get()
  File "/usr/local/lib/python3.10/dist-packages/sqlalchemy/pool/impl.py", line 179, in _do_get
    with util.safe_reraise():
  File "/usr/local/lib/python3.10/dist-packages/sqlalchemy/util/langhelpers.py", line 146, in __exit__
    raise exc_value.with_traceback(exc_tb)
  File "/usr/local/lib/python3.10/dist-packages/sqlalchemy/pool/impl.py", line 177, in _do_get
    return self._create_connection()
  File "/usr/local/lib/python3.10/dist-packages/sqlalchemy/pool/base.py", line 390, in _create_connection
    return _ConnectionRecord(self)
  File "/usr/local/lib/python3.10/dist-packages/sqlalchemy/pool/base.py", line 674, in __init__
    self.__connect()
  File "/usr/local/lib/python3.10/dist-packages/sqlalchemy/pool/base.py", line 900, in __connect
    with util.safe_reraise():
  File "/usr/local/lib/python3.10/dist-packages/sqlalchemy/util/langhelpers.py", line 146, in __exit__
    raise exc_value.with_traceback(exc_tb)
  File "/usr/local/lib/python3.10/dist-packages/sqlalchemy/pool/base.py", line 896, in __connect
    self.dbapi_connection = connection = pool._invoke_creator(self)
  File "/usr/local/lib/python3.10/dist-packages/sqlalchemy/engine/create.py", line 646, in connect
    return dialect.connect(*cargs, **cparams)
  File "/usr/local/lib/python3.10/dist-packages/sqlalchemy/engine/default.py", line 622, in connect
    return self.loaded_dbapi.connect(*cargs, **cparams)
  File "/usr/local/lib/python3.10/dist-packages/psycopg2/__init__.py", line 122, in connect
    conn = _connect(dsn, connection_factory=connection_factory, **kwasync)
sqlalchemy.exc.OperationalError: (psycopg2.OperationalError) connection to server at "localhost" (127.0.0.1), port 5436 failed: FATAL:  password authentication failed for user "postgres"

(Background on this error at: https://sqlalche.me/e/20/e3q8)
2025-01-17 20:33:49,162 - DEBUG - 1 running tasks, waiting for next task to finish
2025-01-17 20:33:49,168 - INFO - Informed scheduler that task   ExtractSalesData__99914b932b   has status   FAILED
2025-01-17 20:33:49,168 - DEBUG - Asking scheduler for work...
2025-01-17 20:33:49,170 - DEBUG - Pending tasks: 6
2025-01-17 20:33:49,170 - INFO - [pid 63092] Worker Worker(salt=7320377462, workers=1, host=LAPTOP-2FUAA63D, username=root, pid=63092) running   TransformMarketingData()
2025-01-17 20:33:49,170 - ERROR - [pid 63092] Worker Worker(salt=7320377462, workers=1, host=LAPTOP-2FUAA63D, username=root, pid=63092) failed    TransformMarketingData()
Traceback (most recent call last):
  File "/usr/local/lib/python3.10/dist-packages/luigi/worker.py", line 210, in run
    new_deps = self._run_get_new_deps()
  File "/usr/local/lib/python3.10/dist-packages/luigi/worker.py", line 138, in _run_get_new_deps
    task_gen = self.task.run()
  File "/root/etl_final_task/etl_luigi.py", line 284, in run
    marketing_data = pd.read_csv(self.input()[0].path)
TypeError: 'LocalTarget' object is not subscriptable
2025-01-17 20:33:49,171 - DEBUG - 1 running tasks, waiting for next task to finish
2025-01-17 20:33:49,175 - INFO - Informed scheduler that task   TransformMarketingData__99914b932b   has status   FAILED
2025-01-17 20:33:49,175 - DEBUG - Asking scheduler for work...
2025-01-17 20:33:49,177 - DEBUG - Pending tasks: 6
2025-01-17 20:33:49,178 - INFO - [pid 63092] Worker Worker(salt=7320377462, workers=1, host=LAPTOP-2FUAA63D, username=root, pid=63092) running   TransformNewsData()
2025-01-17 20:33:49,178 - ERROR - [pid 63092] Worker Worker(salt=7320377462, workers=1, host=LAPTOP-2FUAA63D, username=root, pid=63092) failed    TransformNewsData()
Traceback (most recent call last):
  File "/usr/local/lib/python3.10/dist-packages/luigi/worker.py", line 210, in run
    new_deps = self._run_get_new_deps()
  File "/usr/local/lib/python3.10/dist-packages/luigi/worker.py", line 138, in _run_get_new_deps
    task_gen = self.task.run()
  File "/root/etl_final_task/etl_luigi.py", line 600, in run
    news_data = pd.read_csv(self.input()[0].path)
TypeError: 'LocalTarget' object is not subscriptable
2025-01-17 20:33:49,178 - DEBUG - 1 running tasks, waiting for next task to finish
2025-01-17 20:33:49,182 - INFO - Informed scheduler that task   TransformNewsData__99914b932b   has status   FAILED
2025-01-17 20:33:49,182 - DEBUG - Asking scheduler for work...
2025-01-17 20:33:49,184 - DEBUG - Done
2025-01-17 20:33:49,184 - DEBUG - There are no more tasks to run at this time
2025-01-17 20:33:49,185 - DEBUG - There are 6 pending tasks possibly being run by other workers
2025-01-17 20:33:49,185 - DEBUG - There are 6 pending tasks unique to this worker
2025-01-17 20:33:49,185 - DEBUG - There are 6 pending tasks last scheduled by this worker
2025-01-17 20:33:49,185 - INFO - Worker Worker(salt=7320377462, workers=1, host=LAPTOP-2FUAA63D, username=root, pid=63092) was stopped. Shutting down Keep-Alive thread
2025-01-17 20:33:49,186 - INFO - 
===== Luigi Execution Summary =====

Scheduled 8 tasks of which:
* 2 complete ones were encountered:
    - 1 ExtractMarketingData()
    - 1 ExtractNewsData()
* 3 failed:
    - 1 ExtractSalesData()
    - 1 TransformMarketingData()
    - 1 TransformNewsData()
* 3 were left pending, among these:
    * 3 had failed dependencies:
        - 1 LoadData()
        - 1 TransformSalesData()
        - 1 ValidateData()

This progress looks :( because there were failed tasks

===== Luigi Execution Summary =====

2025-01-17 21:01:41,063 - INFO - [pid 74714] Worker Worker(salt=7057247711, workers=1, host=LAPTOP-2FUAA63D, username=root, pid=74714) done      ExtractMarketingData()
2025-01-17 21:01:41,065 - DEBUG - 1 running tasks, waiting for next task to finish
2025-01-17 21:01:41,067 - INFO - Informed scheduler that task   ExtractMarketingData__99914b932b   has status   DONE
2025-01-17 21:01:41,068 - DEBUG - Asking scheduler for work...
2025-01-17 21:01:41,070 - DEBUG - Pending tasks: 7
2025-01-17 21:01:41,070 - INFO - [pid 74714] Worker Worker(salt=7057247711, workers=1, host=LAPTOP-2FUAA63D, username=root, pid=74714) running   ExtractSalesData()
2025-01-17 21:01:42,322 - INFO - [pid 74714] Worker Worker(salt=7057247711, workers=1, host=LAPTOP-2FUAA63D, username=root, pid=74714) done      ExtractSalesData()
2025-01-17 21:01:42,322 - DEBUG - 1 running tasks, waiting for next task to finish
2025-01-17 21:01:42,325 - INFO - Informed scheduler that task   ExtractSalesData__99914b932b   has status   DONE
2025-01-17 21:01:42,325 - DEBUG - Asking scheduler for work...
2025-01-17 21:01:42,327 - DEBUG - Pending tasks: 6
2025-01-17 21:01:42,327 - INFO - [pid 74714] Worker Worker(salt=7057247711, workers=1, host=LAPTOP-2FUAA63D, username=root, pid=74714) running   ExtractNewsData()
2025-01-17 21:03:41,819 - INFO - [pid 74714] Worker Worker(salt=7057247711, workers=1, host=LAPTOP-2FUAA63D, username=root, pid=74714) done      ExtractNewsData()
2025-01-17 21:03:41,819 - DEBUG - 1 running tasks, waiting for next task to finish
2025-01-17 21:03:41,822 - INFO - Informed scheduler that task   ExtractNewsData__99914b932b   has status   DONE
2025-01-17 21:03:41,822 - DEBUG - Asking scheduler for work...
2025-01-17 21:03:41,825 - DEBUG - Pending tasks: 5
2025-01-17 21:03:41,825 - INFO - [pid 74714] Worker Worker(salt=7057247711, workers=1, host=LAPTOP-2FUAA63D, username=root, pid=74714) running   ValidateData()
2025-01-17 21:03:42,677 - INFO - [pid 74714] Worker Worker(salt=7057247711, workers=1, host=LAPTOP-2FUAA63D, username=root, pid=74714) done      ValidateData()
2025-01-17 21:03:42,677 - DEBUG - 1 running tasks, waiting for next task to finish
2025-01-17 21:03:42,680 - INFO - Informed scheduler that task   ValidateData__99914b932b   has status   DONE
2025-01-17 21:03:42,680 - DEBUG - Asking scheduler for work...
2025-01-17 21:03:42,682 - DEBUG - Pending tasks: 4
2025-01-17 21:03:42,683 - INFO - [pid 74714] Worker Worker(salt=7057247711, workers=1, host=LAPTOP-2FUAA63D, username=root, pid=74714) running   TransformMarketingData()
2025-01-17 21:04:00,402 - INFO - [pid 74714] Worker Worker(salt=7057247711, workers=1, host=LAPTOP-2FUAA63D, username=root, pid=74714) done      TransformMarketingData()
2025-01-17 21:04:00,403 - DEBUG - 1 running tasks, waiting for next task to finish
2025-01-17 21:04:00,406 - INFO - Informed scheduler that task   TransformMarketingData__99914b932b   has status   DONE
2025-01-17 21:04:00,406 - DEBUG - Asking scheduler for work...
2025-01-17 21:04:00,408 - DEBUG - Pending tasks: 3
2025-01-17 21:04:00,408 - INFO - [pid 74714] Worker Worker(salt=7057247711, workers=1, host=LAPTOP-2FUAA63D, username=root, pid=74714) running   TransformSalesData()
2025-01-17 21:04:01,641 - INFO - [pid 74714] Worker Worker(salt=7057247711, workers=1, host=LAPTOP-2FUAA63D, username=root, pid=74714) done      TransformSalesData()
2025-01-17 21:04:01,643 - DEBUG - 1 running tasks, waiting for next task to finish
2025-01-17 21:04:01,645 - INFO - Informed scheduler that task   TransformSalesData__99914b932b   has status   DONE
2025-01-17 21:04:01,646 - DEBUG - Asking scheduler for work...
2025-01-17 21:04:01,648 - DEBUG - Pending tasks: 2
2025-01-17 21:04:01,648 - INFO - [pid 74714] Worker Worker(salt=7057247711, workers=1, host=LAPTOP-2FUAA63D, username=root, pid=74714) running   TransformNewsData()
2025-01-17 21:04:01,685 - INFO - [pid 74714] Worker Worker(salt=7057247711, workers=1, host=LAPTOP-2FUAA63D, username=root, pid=74714) done      TransformNewsData()
2025-01-17 21:04:01,685 - DEBUG - 1 running tasks, waiting for next task to finish
2025-01-17 21:04:01,688 - INFO - Informed scheduler that task   TransformNewsData__99914b932b   has status   DONE
2025-01-17 21:04:01,688 - DEBUG - Asking scheduler for work...
2025-01-17 21:04:01,690 - DEBUG - Pending tasks: 1
2025-01-17 21:04:01,690 - INFO - [pid 74714] Worker Worker(salt=7057247711, workers=1, host=LAPTOP-2FUAA63D, username=root, pid=74714) running   LoadData()
2025-01-17 21:04:03,506 - INFO - [pid 74714] Worker Worker(salt=7057247711, workers=1, host=LAPTOP-2FUAA63D, username=root, pid=74714) done      LoadData()
2025-01-17 21:04:03,507 - DEBUG - 1 running tasks, waiting for next task to finish
2025-01-17 21:04:03,510 - INFO - Informed scheduler that task   LoadData__99914b932b   has status   DONE
2025-01-17 21:04:03,510 - DEBUG - Asking scheduler for work...
2025-01-17 21:04:03,512 - DEBUG - Done
2025-01-17 21:04:03,512 - DEBUG - There are no more tasks to run at this time
2025-01-17 21:04:03,512 - INFO - Worker Worker(salt=7057247711, workers=1, host=LAPTOP-2FUAA63D, username=root, pid=74714) was stopped. Shutting down Keep-Alive thread
2025-01-17 21:04:03,513 - INFO - 
===== Luigi Execution Summary =====

Scheduled 8 tasks of which:
* 8 ran successfully:
    - 1 ExtractMarketingData()
    - 1 ExtractNewsData()
    - 1 ExtractSalesData()
    - 1 LoadData()
    - 1 TransformMarketingData()
    ...

This progress looks :) because there were no failed tasks or missing dependencies

===== Luigi Execution Summary =====

2025-01-17 21:10:23,557 - INFO - [pid 78873] Worker Worker(salt=7600147220, workers=1, host=LAPTOP-2FUAA63D, username=root, pid=78873) done      ValidateData()
2025-01-17 21:10:23,558 - DEBUG - 1 running tasks, waiting for next task to finish
2025-01-17 21:10:23,560 - INFO - Informed scheduler that task   ValidateData__99914b932b   has status   DONE
2025-01-17 21:10:23,561 - DEBUG - Asking scheduler for work...
2025-01-17 21:10:23,562 - DEBUG - Done
2025-01-17 21:10:23,563 - DEBUG - There are no more tasks to run at this time
2025-01-17 21:10:23,563 - INFO - Worker Worker(salt=7600147220, workers=1, host=LAPTOP-2FUAA63D, username=root, pid=78873) was stopped. Shutting down Keep-Alive thread
2025-01-17 21:10:23,564 - INFO - 
===== Luigi Execution Summary =====

Scheduled 8 tasks of which:
* 7 complete ones were encountered:
    - 1 ExtractMarketingData()
    - 1 ExtractNewsData()
    - 1 ExtractSalesData()
    - 1 LoadData()
    - 1 TransformMarketingData()
    ...
* 1 ran successfully:
    - 1 ValidateData()

This progress looks :) because there were no failed tasks or missing dependencies

===== Luigi Execution Summary =====

2025-01-17 21:11:41,546 - INFO - [pid 79471] Worker Worker(salt=1045686420, workers=1, host=LAPTOP-2FUAA63D, username=root, pid=79471) done      ExtractMarketingData()
2025-01-17 21:11:41,547 - DEBUG - 1 running tasks, waiting for next task to finish
2025-01-17 21:11:41,551 - INFO - Informed scheduler that task   ExtractMarketingData__99914b932b   has status   DONE
2025-01-17 21:11:41,552 - DEBUG - Asking scheduler for work...
2025-01-17 21:11:41,554 - DEBUG - Pending tasks: 7
2025-01-17 21:11:41,554 - INFO - [pid 79471] Worker Worker(salt=1045686420, workers=1, host=LAPTOP-2FUAA63D, username=root, pid=79471) running   ExtractSalesData()
2025-01-17 21:11:42,743 - INFO - [pid 79471] Worker Worker(salt=1045686420, workers=1, host=LAPTOP-2FUAA63D, username=root, pid=79471) done      ExtractSalesData()
2025-01-17 21:11:42,743 - DEBUG - 1 running tasks, waiting for next task to finish
2025-01-17 21:11:42,746 - INFO - Informed scheduler that task   ExtractSalesData__99914b932b   has status   DONE
2025-01-17 21:11:42,746 - DEBUG - Asking scheduler for work...
2025-01-17 21:11:42,748 - DEBUG - Pending tasks: 6
2025-01-17 21:11:42,748 - INFO - [pid 79471] Worker Worker(salt=1045686420, workers=1, host=LAPTOP-2FUAA63D, username=root, pid=79471) running   ExtractNewsData()
2025-01-17 21:14:04,153 - INFO - [pid 79471] Worker Worker(salt=1045686420, workers=1, host=LAPTOP-2FUAA63D, username=root, pid=79471) done      ExtractNewsData()
2025-01-17 21:14:04,154 - DEBUG - 1 running tasks, waiting for next task to finish
2025-01-17 21:14:04,156 - INFO - Informed scheduler that task   ExtractNewsData__99914b932b   has status   DONE
2025-01-17 21:14:04,157 - DEBUG - Asking scheduler for work...
2025-01-17 21:14:04,159 - DEBUG - Pending tasks: 5
2025-01-17 21:14:04,159 - INFO - [pid 79471] Worker Worker(salt=1045686420, workers=1, host=LAPTOP-2FUAA63D, username=root, pid=79471) running   ValidateData()
2025-01-17 21:14:04,921 - INFO - [pid 79471] Worker Worker(salt=1045686420, workers=1, host=LAPTOP-2FUAA63D, username=root, pid=79471) done      ValidateData()
2025-01-17 21:14:04,921 - DEBUG - 1 running tasks, waiting for next task to finish
2025-01-17 21:14:04,925 - INFO - Informed scheduler that task   ValidateData__99914b932b   has status   DONE
2025-01-17 21:14:04,925 - DEBUG - Asking scheduler for work...
2025-01-17 21:14:04,927 - DEBUG - Pending tasks: 4
2025-01-17 21:14:04,927 - INFO - [pid 79471] Worker Worker(salt=1045686420, workers=1, host=LAPTOP-2FUAA63D, username=root, pid=79471) running   TransformMarketingData()
2025-01-17 21:14:22,179 - INFO - [pid 79471] Worker Worker(salt=1045686420, workers=1, host=LAPTOP-2FUAA63D, username=root, pid=79471) done      TransformMarketingData()
2025-01-17 21:14:22,179 - DEBUG - 1 running tasks, waiting for next task to finish
2025-01-17 21:14:22,185 - INFO - Informed scheduler that task   TransformMarketingData__99914b932b   has status   DONE
2025-01-17 21:14:22,185 - DEBUG - Asking scheduler for work...
2025-01-17 21:14:22,188 - DEBUG - Pending tasks: 3
2025-01-17 21:14:22,188 - INFO - [pid 79471] Worker Worker(salt=1045686420, workers=1, host=LAPTOP-2FUAA63D, username=root, pid=79471) running   TransformSalesData()
2025-01-17 21:14:23,387 - INFO - [pid 79471] Worker Worker(salt=1045686420, workers=1, host=LAPTOP-2FUAA63D, username=root, pid=79471) done      TransformSalesData()
2025-01-17 21:14:23,387 - DEBUG - 1 running tasks, waiting for next task to finish
2025-01-17 21:14:23,390 - INFO - Informed scheduler that task   TransformSalesData__99914b932b   has status   DONE
2025-01-17 21:14:23,390 - DEBUG - Asking scheduler for work...
2025-01-17 21:14:23,392 - DEBUG - Pending tasks: 2
2025-01-17 21:14:23,392 - INFO - [pid 79471] Worker Worker(salt=1045686420, workers=1, host=LAPTOP-2FUAA63D, username=root, pid=79471) running   TransformNewsData()
2025-01-17 21:14:23,431 - INFO - [pid 79471] Worker Worker(salt=1045686420, workers=1, host=LAPTOP-2FUAA63D, username=root, pid=79471) done      TransformNewsData()
2025-01-17 21:14:23,431 - DEBUG - 1 running tasks, waiting for next task to finish
2025-01-17 21:14:23,433 - INFO - Informed scheduler that task   TransformNewsData__99914b932b   has status   DONE
2025-01-17 21:14:23,433 - DEBUG - Asking scheduler for work...
2025-01-17 21:14:23,435 - DEBUG - Pending tasks: 1
2025-01-17 21:14:23,435 - INFO - [pid 79471] Worker Worker(salt=1045686420, workers=1, host=LAPTOP-2FUAA63D, username=root, pid=79471) running   LoadData()
2025-01-17 21:14:25,221 - INFO - [pid 79471] Worker Worker(salt=1045686420, workers=1, host=LAPTOP-2FUAA63D, username=root, pid=79471) done      LoadData()
2025-01-17 21:14:25,222 - DEBUG - 1 running tasks, waiting for next task to finish
2025-01-17 21:14:25,225 - INFO - Informed scheduler that task   LoadData__99914b932b   has status   DONE
2025-01-17 21:14:25,225 - DEBUG - Asking scheduler for work...
2025-01-17 21:14:25,227 - DEBUG - Done
2025-01-17 21:14:25,227 - DEBUG - There are no more tasks to run at this time
2025-01-17 21:14:25,227 - INFO - Worker Worker(salt=1045686420, workers=1, host=LAPTOP-2FUAA63D, username=root, pid=79471) was stopped. Shutting down Keep-Alive thread
2025-01-17 21:14:25,228 - INFO - 
===== Luigi Execution Summary =====

Scheduled 8 tasks of which:
* 8 ran successfully:
    - 1 ExtractMarketingData()
    - 1 ExtractNewsData()
    - 1 ExtractSalesData()
    - 1 LoadData()
    - 1 TransformMarketingData()
    ...

This progress looks :) because there were no failed tasks or missing dependencies

===== Luigi Execution Summary =====

2025-01-17 21:32:30,826 - INFO - [pid 88672] Worker Worker(salt=440833471, workers=1, host=LAPTOP-2FUAA63D, username=root, pid=88672) done      ExtractMarketingData()
2025-01-17 21:32:30,828 - DEBUG - 1 running tasks, waiting for next task to finish
2025-01-17 21:32:30,832 - INFO - Informed scheduler that task   ExtractMarketingData__99914b932b   has status   DONE
2025-01-17 21:32:30,832 - DEBUG - Asking scheduler for work...
2025-01-17 21:32:30,834 - DEBUG - Pending tasks: 7
2025-01-17 21:32:30,834 - INFO - [pid 88672] Worker Worker(salt=440833471, workers=1, host=LAPTOP-2FUAA63D, username=root, pid=88672) running   ExtractSalesData()
2025-01-17 21:32:32,024 - INFO - [pid 88672] Worker Worker(salt=440833471, workers=1, host=LAPTOP-2FUAA63D, username=root, pid=88672) done      ExtractSalesData()
2025-01-17 21:32:32,024 - DEBUG - 1 running tasks, waiting for next task to finish
2025-01-17 21:32:32,027 - INFO - Informed scheduler that task   ExtractSalesData__99914b932b   has status   DONE
2025-01-17 21:32:32,027 - DEBUG - Asking scheduler for work...
2025-01-17 21:32:32,029 - DEBUG - Pending tasks: 6
2025-01-17 21:32:32,029 - INFO - [pid 88672] Worker Worker(salt=440833471, workers=1, host=LAPTOP-2FUAA63D, username=root, pid=88672) running   ExtractNewsData()
2025-01-17 21:34:37,248 - INFO - [pid 88672] Worker Worker(salt=440833471, workers=1, host=LAPTOP-2FUAA63D, username=root, pid=88672) done      ExtractNewsData()
2025-01-17 21:34:37,248 - DEBUG - 1 running tasks, waiting for next task to finish
2025-01-17 21:34:37,252 - INFO - Informed scheduler that task   ExtractNewsData__99914b932b   has status   DONE
2025-01-17 21:34:37,252 - DEBUG - Asking scheduler for work...
2025-01-17 21:34:37,254 - DEBUG - Pending tasks: 5
2025-01-17 21:34:37,254 - INFO - [pid 88672] Worker Worker(salt=440833471, workers=1, host=LAPTOP-2FUAA63D, username=root, pid=88672) running   ValidateData()
2025-01-17 21:34:38,033 - INFO - [pid 88672] Worker Worker(salt=440833471, workers=1, host=LAPTOP-2FUAA63D, username=root, pid=88672) done      ValidateData()
2025-01-17 21:34:38,034 - DEBUG - 1 running tasks, waiting for next task to finish
2025-01-17 21:34:38,037 - INFO - Informed scheduler that task   ValidateData__99914b932b   has status   DONE
2025-01-17 21:34:38,038 - DEBUG - Asking scheduler for work...
2025-01-17 21:34:38,040 - DEBUG - Pending tasks: 4
2025-01-17 21:34:38,041 - INFO - [pid 88672] Worker Worker(salt=440833471, workers=1, host=LAPTOP-2FUAA63D, username=root, pid=88672) running   TransformMarketingData()
2025-01-17 21:34:55,309 - INFO - [pid 88672] Worker Worker(salt=440833471, workers=1, host=LAPTOP-2FUAA63D, username=root, pid=88672) done      TransformMarketingData()
2025-01-17 21:34:55,310 - DEBUG - 1 running tasks, waiting for next task to finish
2025-01-17 21:34:55,313 - INFO - Informed scheduler that task   TransformMarketingData__99914b932b   has status   DONE
2025-01-17 21:34:55,313 - DEBUG - Asking scheduler for work...
2025-01-17 21:34:55,315 - DEBUG - Pending tasks: 3
2025-01-17 21:34:55,315 - INFO - [pid 88672] Worker Worker(salt=440833471, workers=1, host=LAPTOP-2FUAA63D, username=root, pid=88672) running   TransformSalesData()
2025-01-17 21:34:56,530 - INFO - [pid 88672] Worker Worker(salt=440833471, workers=1, host=LAPTOP-2FUAA63D, username=root, pid=88672) done      TransformSalesData()
2025-01-17 21:34:56,530 - DEBUG - 1 running tasks, waiting for next task to finish
2025-01-17 21:34:56,533 - INFO - Informed scheduler that task   TransformSalesData__99914b932b   has status   DONE
2025-01-17 21:34:56,533 - DEBUG - Asking scheduler for work...
2025-01-17 21:34:56,535 - DEBUG - Pending tasks: 2
2025-01-17 21:34:56,536 - INFO - [pid 88672] Worker Worker(salt=440833471, workers=1, host=LAPTOP-2FUAA63D, username=root, pid=88672) running   TransformNewsData()
2025-01-17 21:34:56,574 - INFO - [pid 88672] Worker Worker(salt=440833471, workers=1, host=LAPTOP-2FUAA63D, username=root, pid=88672) done      TransformNewsData()
2025-01-17 21:34:56,574 - DEBUG - 1 running tasks, waiting for next task to finish
2025-01-17 21:34:56,577 - INFO - Informed scheduler that task   TransformNewsData__99914b932b   has status   DONE
2025-01-17 21:34:56,577 - DEBUG - Asking scheduler for work...
2025-01-17 21:34:56,579 - DEBUG - Pending tasks: 1
2025-01-17 21:34:56,579 - INFO - [pid 88672] Worker Worker(salt=440833471, workers=1, host=LAPTOP-2FUAA63D, username=root, pid=88672) running   LoadData()
2025-01-17 21:34:58,342 - INFO - [pid 88672] Worker Worker(salt=440833471, workers=1, host=LAPTOP-2FUAA63D, username=root, pid=88672) done      LoadData()
2025-01-17 21:34:58,343 - DEBUG - 1 running tasks, waiting for next task to finish
2025-01-17 21:34:58,346 - INFO - Informed scheduler that task   LoadData__99914b932b   has status   DONE
2025-01-17 21:34:58,346 - DEBUG - Asking scheduler for work...
2025-01-17 21:34:58,348 - DEBUG - Done
2025-01-17 21:34:58,348 - DEBUG - There are no more tasks to run at this time
2025-01-17 21:34:58,348 - INFO - Worker Worker(salt=440833471, workers=1, host=LAPTOP-2FUAA63D, username=root, pid=88672) was stopped. Shutting down Keep-Alive thread
2025-01-17 21:34:58,350 - INFO - 
===== Luigi Execution Summary =====

Scheduled 8 tasks of which:
* 8 ran successfully:
    - 1 ExtractMarketingData()
    - 1 ExtractNewsData()
    - 1 ExtractSalesData()
    - 1 LoadData()
    - 1 TransformMarketingData()
    ...

This progress looks :) because there were no failed tasks or missing dependencies

===== Luigi Execution Summary =====

2025-01-17 21:39:14,502 - INFO - [pid 92006] Worker Worker(salt=4255279544, workers=1, host=LAPTOP-2FUAA63D, username=root, pid=92006) done      ExtractMarketingData()
2025-01-17 21:39:14,503 - DEBUG - 1 running tasks, waiting for next task to finish
2025-01-17 21:39:14,506 - INFO - Informed scheduler that task   ExtractMarketingData__99914b932b   has status   DONE
2025-01-17 21:39:14,506 - DEBUG - Asking scheduler for work...
2025-01-17 21:39:14,508 - DEBUG - Pending tasks: 7
2025-01-17 21:39:14,509 - INFO - [pid 92006] Worker Worker(salt=4255279544, workers=1, host=LAPTOP-2FUAA63D, username=root, pid=92006) running   ExtractSalesData()
2025-01-17 21:39:15,692 - INFO - [pid 92006] Worker Worker(salt=4255279544, workers=1, host=LAPTOP-2FUAA63D, username=root, pid=92006) done      ExtractSalesData()
2025-01-17 21:39:15,692 - DEBUG - 1 running tasks, waiting for next task to finish
2025-01-17 21:39:15,695 - INFO - Informed scheduler that task   ExtractSalesData__99914b932b   has status   DONE
2025-01-17 21:39:15,696 - DEBUG - Asking scheduler for work...
2025-01-17 21:39:15,698 - DEBUG - Pending tasks: 6
2025-01-17 21:39:15,698 - INFO - [pid 92006] Worker Worker(salt=4255279544, workers=1, host=LAPTOP-2FUAA63D, username=root, pid=92006) running   ExtractNewsData()
2025-01-17 21:45:32,682 - INFO - [pid 92006] Worker Worker(salt=4255279544, workers=1, host=LAPTOP-2FUAA63D, username=root, pid=92006) done      ExtractNewsData()
2025-01-17 21:45:32,682 - DEBUG - 1 running tasks, waiting for next task to finish
2025-01-17 21:45:32,685 - INFO - Informed scheduler that task   ExtractNewsData__99914b932b   has status   DONE
2025-01-17 21:45:32,686 - DEBUG - Asking scheduler for work...
2025-01-17 21:45:32,688 - DEBUG - Pending tasks: 5
2025-01-17 21:45:32,688 - INFO - [pid 92006] Worker Worker(salt=4255279544, workers=1, host=LAPTOP-2FUAA63D, username=root, pid=92006) running   ValidateData()
2025-01-17 21:45:33,591 - INFO - [pid 92006] Worker Worker(salt=4255279544, workers=1, host=LAPTOP-2FUAA63D, username=root, pid=92006) done      ValidateData()
2025-01-17 21:45:33,591 - DEBUG - 1 running tasks, waiting for next task to finish
2025-01-17 21:45:33,595 - INFO - Informed scheduler that task   ValidateData__99914b932b   has status   DONE
2025-01-17 21:45:33,595 - DEBUG - Asking scheduler for work...
2025-01-17 21:45:33,597 - DEBUG - Pending tasks: 4
2025-01-17 21:45:33,597 - INFO - [pid 92006] Worker Worker(salt=4255279544, workers=1, host=LAPTOP-2FUAA63D, username=root, pid=92006) running   TransformMarketingData()
2025-01-17 21:46:00,099 - INFO - [pid 92006] Worker Worker(salt=4255279544, workers=1, host=LAPTOP-2FUAA63D, username=root, pid=92006) done      TransformMarketingData()
2025-01-17 21:46:00,100 - DEBUG - 1 running tasks, waiting for next task to finish
2025-01-17 21:46:00,103 - INFO - Informed scheduler that task   TransformMarketingData__99914b932b   has status   DONE
2025-01-17 21:46:00,104 - DEBUG - Asking scheduler for work...
2025-01-17 21:46:00,106 - DEBUG - Pending tasks: 3
2025-01-17 21:46:00,106 - INFO - [pid 92006] Worker Worker(salt=4255279544, workers=1, host=LAPTOP-2FUAA63D, username=root, pid=92006) running   TransformSalesData()
2025-01-17 21:46:01,541 - INFO - [pid 92006] Worker Worker(salt=4255279544, workers=1, host=LAPTOP-2FUAA63D, username=root, pid=92006) done      TransformSalesData()
2025-01-17 21:46:01,542 - DEBUG - 1 running tasks, waiting for next task to finish
2025-01-17 21:46:01,545 - INFO - Informed scheduler that task   TransformSalesData__99914b932b   has status   DONE
2025-01-17 21:46:01,545 - DEBUG - Asking scheduler for work...
2025-01-17 21:46:01,547 - DEBUG - Pending tasks: 2
2025-01-17 21:46:01,547 - INFO - [pid 92006] Worker Worker(salt=4255279544, workers=1, host=LAPTOP-2FUAA63D, username=root, pid=92006) running   TransformNewsData()
2025-01-17 21:46:01,594 - INFO - [pid 92006] Worker Worker(salt=4255279544, workers=1, host=LAPTOP-2FUAA63D, username=root, pid=92006) done      TransformNewsData()
2025-01-17 21:46:01,594 - DEBUG - 1 running tasks, waiting for next task to finish
2025-01-17 21:46:01,597 - INFO - Informed scheduler that task   TransformNewsData__99914b932b   has status   DONE
2025-01-17 21:46:01,598 - DEBUG - Asking scheduler for work...
2025-01-17 21:46:01,600 - DEBUG - Pending tasks: 1
2025-01-17 21:46:01,600 - INFO - [pid 92006] Worker Worker(salt=4255279544, workers=1, host=LAPTOP-2FUAA63D, username=root, pid=92006) running   LoadData()
2025-01-17 21:46:03,618 - INFO - [pid 92006] Worker Worker(salt=4255279544, workers=1, host=LAPTOP-2FUAA63D, username=root, pid=92006) done      LoadData()
2025-01-17 21:46:03,618 - DEBUG - 1 running tasks, waiting for next task to finish
2025-01-17 21:46:03,621 - INFO - Informed scheduler that task   LoadData__99914b932b   has status   DONE
2025-01-17 21:46:03,621 - DEBUG - Asking scheduler for work...
2025-01-17 21:46:03,623 - DEBUG - Done
2025-01-17 21:46:03,623 - DEBUG - There are no more tasks to run at this time
2025-01-17 21:46:03,623 - INFO - Worker Worker(salt=4255279544, workers=1, host=LAPTOP-2FUAA63D, username=root, pid=92006) was stopped. Shutting down Keep-Alive thread
2025-01-17 21:46:03,624 - INFO - 
===== Luigi Execution Summary =====

Scheduled 8 tasks of which:
* 8 ran successfully:
    - 1 ExtractMarketingData()
    - 1 ExtractNewsData()
    - 1 ExtractSalesData()
    - 1 LoadData()
    - 1 TransformMarketingData()
    ...

This progress looks :) because there were no failed tasks or missing dependencies

===== Luigi Execution Summary =====

2025-01-18 05:22:08,576 - INFO - [pid 7465] Worker Worker(salt=8583796557, workers=1, host=LAPTOP-2FUAA63D, username=root, pid=7465) done      ExtractMarketingData()
2025-01-18 05:22:08,576 - DEBUG - 1 running tasks, waiting for next task to finish
2025-01-18 05:22:08,579 - INFO - Informed scheduler that task   ExtractMarketingData__99914b932b   has status   DONE
2025-01-18 05:22:08,579 - DEBUG - Asking scheduler for work...
2025-01-18 05:22:08,581 - DEBUG - Pending tasks: 7
2025-01-18 05:22:08,581 - INFO - [pid 7465] Worker Worker(salt=8583796557, workers=1, host=LAPTOP-2FUAA63D, username=root, pid=7465) running   ExtractSalesData()
2025-01-18 05:22:09,795 - INFO - [pid 7465] Worker Worker(salt=8583796557, workers=1, host=LAPTOP-2FUAA63D, username=root, pid=7465) done      ExtractSalesData()
2025-01-18 05:22:09,795 - DEBUG - 1 running tasks, waiting for next task to finish
2025-01-18 05:22:09,798 - INFO - Informed scheduler that task   ExtractSalesData__99914b932b   has status   DONE
2025-01-18 05:22:09,798 - DEBUG - Asking scheduler for work...
2025-01-18 05:22:09,800 - DEBUG - Pending tasks: 6
2025-01-18 05:22:09,800 - INFO - [pid 7465] Worker Worker(salt=8583796557, workers=1, host=LAPTOP-2FUAA63D, username=root, pid=7465) running   ExtractNewsData()
2025-01-18 05:23:40,546 - INFO - [pid 7465] Worker Worker(salt=8583796557, workers=1, host=LAPTOP-2FUAA63D, username=root, pid=7465) done      ExtractNewsData()
2025-01-18 05:23:40,547 - DEBUG - 1 running tasks, waiting for next task to finish
2025-01-18 05:23:40,549 - INFO - Informed scheduler that task   ExtractNewsData__99914b932b   has status   DONE
2025-01-18 05:23:40,550 - DEBUG - Asking scheduler for work...
2025-01-18 05:23:40,552 - DEBUG - Pending tasks: 5
2025-01-18 05:23:40,552 - INFO - [pid 7465] Worker Worker(salt=8583796557, workers=1, host=LAPTOP-2FUAA63D, username=root, pid=7465) running   ValidateData()
2025-01-18 05:23:41,372 - INFO - [pid 7465] Worker Worker(salt=8583796557, workers=1, host=LAPTOP-2FUAA63D, username=root, pid=7465) done      ValidateData()
2025-01-18 05:23:41,372 - DEBUG - 1 running tasks, waiting for next task to finish
2025-01-18 05:23:41,375 - INFO - Informed scheduler that task   ValidateData__99914b932b   has status   DONE
2025-01-18 05:23:41,375 - DEBUG - Asking scheduler for work...
2025-01-18 05:23:41,377 - DEBUG - Pending tasks: 4
2025-01-18 05:23:41,377 - INFO - [pid 7465] Worker Worker(salt=8583796557, workers=1, host=LAPTOP-2FUAA63D, username=root, pid=7465) running   TransformMarketingData()
2025-01-18 05:23:59,058 - INFO - [pid 7465] Worker Worker(salt=8583796557, workers=1, host=LAPTOP-2FUAA63D, username=root, pid=7465) done      TransformMarketingData()
2025-01-18 05:23:59,059 - DEBUG - 1 running tasks, waiting for next task to finish
2025-01-18 05:23:59,062 - INFO - Informed scheduler that task   TransformMarketingData__99914b932b   has status   DONE
2025-01-18 05:23:59,062 - DEBUG - Asking scheduler for work...
2025-01-18 05:23:59,064 - DEBUG - Pending tasks: 3
2025-01-18 05:23:59,064 - INFO - [pid 7465] Worker Worker(salt=8583796557, workers=1, host=LAPTOP-2FUAA63D, username=root, pid=7465) running   TransformSalesData()
2025-01-18 05:24:00,336 - INFO - [pid 7465] Worker Worker(salt=8583796557, workers=1, host=LAPTOP-2FUAA63D, username=root, pid=7465) done      TransformSalesData()
2025-01-18 05:24:00,336 - DEBUG - 1 running tasks, waiting for next task to finish
2025-01-18 05:24:00,339 - INFO - Informed scheduler that task   TransformSalesData__99914b932b   has status   DONE
2025-01-18 05:24:00,339 - DEBUG - Asking scheduler for work...
2025-01-18 05:24:00,341 - DEBUG - Pending tasks: 2
2025-01-18 05:24:00,341 - INFO - [pid 7465] Worker Worker(salt=8583796557, workers=1, host=LAPTOP-2FUAA63D, username=root, pid=7465) running   TransformNewsData()
2025-01-18 05:24:00,378 - INFO - [pid 7465] Worker Worker(salt=8583796557, workers=1, host=LAPTOP-2FUAA63D, username=root, pid=7465) done      TransformNewsData()
2025-01-18 05:24:00,379 - DEBUG - 1 running tasks, waiting for next task to finish
2025-01-18 05:24:00,382 - INFO - Informed scheduler that task   TransformNewsData__99914b932b   has status   DONE
2025-01-18 05:24:00,382 - DEBUG - Asking scheduler for work...
2025-01-18 05:24:00,384 - DEBUG - Pending tasks: 1
2025-01-18 05:24:00,384 - INFO - [pid 7465] Worker Worker(salt=8583796557, workers=1, host=LAPTOP-2FUAA63D, username=root, pid=7465) running   LoadData()
2025-01-18 05:24:02,277 - INFO - [pid 7465] Worker Worker(salt=8583796557, workers=1, host=LAPTOP-2FUAA63D, username=root, pid=7465) done      LoadData()
2025-01-18 05:24:02,278 - DEBUG - 1 running tasks, waiting for next task to finish
2025-01-18 05:24:02,281 - INFO - Informed scheduler that task   LoadData__99914b932b   has status   DONE
2025-01-18 05:24:02,281 - DEBUG - Asking scheduler for work...
2025-01-18 05:24:02,284 - DEBUG - Done
2025-01-18 05:24:02,284 - DEBUG - There are no more tasks to run at this time
2025-01-18 05:24:02,284 - INFO - Worker Worker(salt=8583796557, workers=1, host=LAPTOP-2FUAA63D, username=root, pid=7465) was stopped. Shutting down Keep-Alive thread
2025-01-18 05:24:02,285 - INFO - 
===== Luigi Execution Summary =====

Scheduled 8 tasks of which:
* 8 ran successfully:
    - 1 ExtractMarketingData()
    - 1 ExtractNewsData()
    - 1 ExtractSalesData()
    - 1 LoadData()
    - 1 TransformMarketingData()
    ...

This progress looks :) because there were no failed tasks or missing dependencies

===== Luigi Execution Summary =====

2025-01-18 05:41:23,579 - INFO - [pid 16430] Worker Worker(salt=2285939953, workers=1, host=LAPTOP-2FUAA63D, username=root, pid=16430) done      LoadData()
2025-01-18 05:41:23,581 - DEBUG - 1 running tasks, waiting for next task to finish
2025-01-18 05:41:23,585 - INFO - Informed scheduler that task   LoadData__99914b932b   has status   DONE
2025-01-18 05:41:23,585 - DEBUG - Asking scheduler for work...
2025-01-18 05:41:23,587 - DEBUG - Done
2025-01-18 05:41:23,587 - DEBUG - There are no more tasks to run at this time
2025-01-18 05:41:23,587 - INFO - Worker Worker(salt=2285939953, workers=1, host=LAPTOP-2FUAA63D, username=root, pid=16430) was stopped. Shutting down Keep-Alive thread
2025-01-18 05:41:23,589 - INFO - 
===== Luigi Execution Summary =====

Scheduled 4 tasks of which:
* 3 complete ones were encountered:
    - 1 TransformMarketingData()
    - 1 TransformNewsData()
    - 1 TransformSalesData()
* 1 ran successfully:
    - 1 LoadData()

This progress looks :) because there were no failed tasks or missing dependencies

===== Luigi Execution Summary =====

2025-01-18 14:55:11,759 - INFO - [pid 29373] Worker Worker(salt=7568126960, workers=1, host=LAPTOP-2FUAA63D, username=root, pid=29373) done      ExtractMarketingData()
2025-01-18 14:55:11,761 - DEBUG - 1 running tasks, waiting for next task to finish
2025-01-18 14:55:11,764 - INFO - Informed scheduler that task   ExtractMarketingData__99914b932b   has status   DONE
2025-01-18 14:55:11,764 - DEBUG - Asking scheduler for work...
2025-01-18 14:55:11,766 - DEBUG - Pending tasks: 7
2025-01-18 14:55:11,766 - INFO - [pid 29373] Worker Worker(salt=7568126960, workers=1, host=LAPTOP-2FUAA63D, username=root, pid=29373) running   ExtractSalesData()
2025-01-18 14:55:13,012 - INFO - [pid 29373] Worker Worker(salt=7568126960, workers=1, host=LAPTOP-2FUAA63D, username=root, pid=29373) done      ExtractSalesData()
2025-01-18 14:55:13,012 - DEBUG - 1 running tasks, waiting for next task to finish
2025-01-18 14:55:13,015 - INFO - Informed scheduler that task   ExtractSalesData__99914b932b   has status   DONE
2025-01-18 14:55:13,015 - DEBUG - Asking scheduler for work...
2025-01-18 14:55:13,017 - DEBUG - Pending tasks: 6
2025-01-18 14:55:13,017 - INFO - [pid 29373] Worker Worker(salt=7568126960, workers=1, host=LAPTOP-2FUAA63D, username=root, pid=29373) running   ExtractNewsData()
2025-01-18 14:55:54,056 - ERROR - [pid 29373] Worker Worker(salt=7568126960, workers=1, host=LAPTOP-2FUAA63D, username=root, pid=29373) failed    ExtractNewsData()
Traceback (most recent call last):
  File "/root/etl_final_task/etl_luigi.py", line 193, in run
    news_created = soup2.find("div", class_ = "text-cnn_grey text-sm mb-6").text.strip()
AttributeError: 'NoneType' object has no attribute 'text'

During handling of the above exception, another exception occurred:

Traceback (most recent call last):
  File "/usr/local/lib/python3.10/dist-packages/luigi/worker.py", line 210, in run
    new_deps = self._run_get_new_deps()
  File "/usr/local/lib/python3.10/dist-packages/luigi/worker.py", line 138, in _run_get_new_deps
    task_gen = self.task.run()
  File "/root/etl_final_task/etl_luigi.py", line 218, in run
    raise Exception(f"There's some error: {e}")
Exception: There's some error: 'NoneType' object has no attribute 'text'
2025-01-18 14:55:54,057 - DEBUG - 1 running tasks, waiting for next task to finish
2025-01-18 14:55:54,061 - INFO - Informed scheduler that task   ExtractNewsData__99914b932b   has status   FAILED
2025-01-18 14:55:54,061 - DEBUG - Asking scheduler for work...
2025-01-18 14:55:54,063 - DEBUG - Pending tasks: 6
2025-01-18 14:55:54,064 - INFO - [pid 29373] Worker Worker(salt=7568126960, workers=1, host=LAPTOP-2FUAA63D, username=root, pid=29373) running   TransformMarketingData()
2025-01-18 14:56:12,553 - INFO - [pid 29373] Worker Worker(salt=7568126960, workers=1, host=LAPTOP-2FUAA63D, username=root, pid=29373) done      TransformMarketingData()
2025-01-18 14:56:12,553 - DEBUG - 1 running tasks, waiting for next task to finish
2025-01-18 14:56:12,557 - INFO - Informed scheduler that task   TransformMarketingData__99914b932b   has status   DONE
2025-01-18 14:56:12,557 - DEBUG - Asking scheduler for work...
2025-01-18 14:56:12,559 - DEBUG - Pending tasks: 5
2025-01-18 14:56:12,559 - INFO - [pid 29373] Worker Worker(salt=7568126960, workers=1, host=LAPTOP-2FUAA63D, username=root, pid=29373) running   TransformSalesData()
2025-01-18 14:56:13,859 - INFO - [pid 29373] Worker Worker(salt=7568126960, workers=1, host=LAPTOP-2FUAA63D, username=root, pid=29373) done      TransformSalesData()
2025-01-18 14:56:13,860 - DEBUG - 1 running tasks, waiting for next task to finish
2025-01-18 14:56:13,863 - INFO - Informed scheduler that task   TransformSalesData__99914b932b   has status   DONE
2025-01-18 14:56:13,863 - DEBUG - Asking scheduler for work...
2025-01-18 14:56:13,865 - DEBUG - Done
2025-01-18 14:56:13,865 - DEBUG - There are no more tasks to run at this time
2025-01-18 14:56:13,865 - DEBUG - There are 4 pending tasks possibly being run by other workers
2025-01-18 14:56:13,865 - DEBUG - There are 4 pending tasks unique to this worker
2025-01-18 14:56:13,865 - DEBUG - There are 4 pending tasks last scheduled by this worker
2025-01-18 14:56:13,865 - INFO - Worker Worker(salt=7568126960, workers=1, host=LAPTOP-2FUAA63D, username=root, pid=29373) was stopped. Shutting down Keep-Alive thread
2025-01-18 14:56:13,867 - INFO - 
===== Luigi Execution Summary =====

Scheduled 8 tasks of which:
* 4 ran successfully:
    - 1 ExtractMarketingData()
    - 1 ExtractSalesData()
    - 1 TransformMarketingData()
    - 1 TransformSalesData()
* 1 failed:
    - 1 ExtractNewsData()
* 3 were left pending, among these:
    * 3 had failed dependencies:
        - 1 LoadData()
        - 1 TransformNewsData()
        - 1 ValidateData()

This progress looks :( because there were failed tasks

===== Luigi Execution Summary =====

2025-01-18 15:00:23,692 - INFO - [pid 31794] Worker Worker(salt=6200395780, workers=1, host=LAPTOP-2FUAA63D, username=root, pid=31794) done      ExtractMarketingData()
2025-01-18 15:00:23,693 - DEBUG - 1 running tasks, waiting for next task to finish
2025-01-18 15:00:23,696 - INFO - Informed scheduler that task   ExtractMarketingData__99914b932b   has status   DONE
2025-01-18 15:00:23,697 - DEBUG - Asking scheduler for work...
2025-01-18 15:00:23,699 - DEBUG - Pending tasks: 7
2025-01-18 15:00:23,699 - INFO - [pid 31794] Worker Worker(salt=6200395780, workers=1, host=LAPTOP-2FUAA63D, username=root, pid=31794) running   ExtractSalesData()
2025-01-18 15:00:24,800 - INFO - [pid 31794] Worker Worker(salt=6200395780, workers=1, host=LAPTOP-2FUAA63D, username=root, pid=31794) done      ExtractSalesData()
2025-01-18 15:00:24,801 - DEBUG - 1 running tasks, waiting for next task to finish
2025-01-18 15:00:24,804 - INFO - Informed scheduler that task   ExtractSalesData__99914b932b   has status   DONE
2025-01-18 15:00:24,804 - DEBUG - Asking scheduler for work...
2025-01-18 15:00:24,806 - DEBUG - Pending tasks: 6
2025-01-18 15:00:24,806 - INFO - [pid 31794] Worker Worker(salt=6200395780, workers=1, host=LAPTOP-2FUAA63D, username=root, pid=31794) running   ExtractNewsData()
2025-01-18 15:01:18,979 - ERROR - [pid 31794] Worker Worker(salt=6200395780, workers=1, host=LAPTOP-2FUAA63D, username=root, pid=31794) failed    ExtractNewsData()
Traceback (most recent call last):
  File "/root/etl_final_task/etl_luigi.py", line 193, in run
    news_created = soup2.find("div", class_ = "text-cnn_grey text-sm mb-6").text.strip()
AttributeError: 'NoneType' object has no attribute 'text'

During handling of the above exception, another exception occurred:

Traceback (most recent call last):
  File "/usr/local/lib/python3.10/dist-packages/luigi/worker.py", line 210, in run
    new_deps = self._run_get_new_deps()
  File "/usr/local/lib/python3.10/dist-packages/luigi/worker.py", line 138, in _run_get_new_deps
    task_gen = self.task.run()
  File "/root/etl_final_task/etl_luigi.py", line 218, in run
    raise Exception(f"There's some error: {e}")
Exception: There's some error: 'NoneType' object has no attribute 'text'
2025-01-18 15:01:18,980 - DEBUG - 1 running tasks, waiting for next task to finish
2025-01-18 15:01:18,984 - INFO - Informed scheduler that task   ExtractNewsData__99914b932b   has status   FAILED
2025-01-18 15:01:18,984 - DEBUG - Asking scheduler for work...
2025-01-18 15:01:18,987 - DEBUG - Pending tasks: 6
2025-01-18 15:01:18,987 - INFO - [pid 31794] Worker Worker(salt=6200395780, workers=1, host=LAPTOP-2FUAA63D, username=root, pid=31794) running   TransformMarketingData()
2025-01-18 15:01:19,418 - ERROR - [pid 31794] Worker Worker(salt=6200395780, workers=1, host=LAPTOP-2FUAA63D, username=root, pid=31794) failed    TransformMarketingData()
Traceback (most recent call last):
  File "/usr/local/lib/python3.10/dist-packages/luigi/worker.py", line 210, in run
    new_deps = self._run_get_new_deps()
  File "/usr/local/lib/python3.10/dist-packages/luigi/worker.py", line 138, in _run_get_new_deps
    task_gen = self.task.run()
  File "/root/etl_final_task/etl_luigi.py", line 339, in run
    availability.append(CONVERT_VALUES1, inplace=True)
  File "/usr/local/lib/python3.10/dist-packages/pandas/core/generic.py", line 6299, in __getattr__
    return object.__getattribute__(self, name)
AttributeError: 'Series' object has no attribute 'append'
2025-01-18 15:01:19,422 - DEBUG - 1 running tasks, waiting for next task to finish
2025-01-18 15:01:19,426 - INFO - Informed scheduler that task   TransformMarketingData__99914b932b   has status   FAILED
2025-01-18 15:01:19,426 - DEBUG - Asking scheduler for work...
2025-01-18 15:01:19,428 - DEBUG - Pending tasks: 6
2025-01-18 15:01:19,428 - INFO - [pid 31794] Worker Worker(salt=6200395780, workers=1, host=LAPTOP-2FUAA63D, username=root, pid=31794) running   TransformSalesData()
2025-01-18 15:01:19,885 - ERROR - [pid 31794] Worker Worker(salt=6200395780, workers=1, host=LAPTOP-2FUAA63D, username=root, pid=31794) failed    TransformSalesData()
Traceback (most recent call last):
  File "/usr/local/lib/python3.10/dist-packages/luigi/worker.py", line 210, in run
    new_deps = self._run_get_new_deps()
  File "/usr/local/lib/python3.10/dist-packages/luigi/worker.py", line 138, in _run_get_new_deps
    task_gen = self.task.run()
  File "/root/etl_final_task/etl_luigi.py", line 504, in run
    sales_data['no_of_ratings'] = sales_data['no_of_ratings'].str.append(r'\D', '', regex=True)
AttributeError: 'StringMethods' object has no attribute 'append'
2025-01-18 15:01:19,889 - DEBUG - 1 running tasks, waiting for next task to finish
2025-01-18 15:01:19,893 - INFO - Informed scheduler that task   TransformSalesData__99914b932b   has status   FAILED
2025-01-18 15:01:19,893 - DEBUG - Asking scheduler for work...
2025-01-18 15:01:19,895 - DEBUG - Done
2025-01-18 15:01:19,895 - DEBUG - There are no more tasks to run at this time
2025-01-18 15:01:19,895 - DEBUG - There are 6 pending tasks possibly being run by other workers
2025-01-18 15:01:19,895 - DEBUG - There are 6 pending tasks unique to this worker
2025-01-18 15:01:19,895 - DEBUG - There are 6 pending tasks last scheduled by this worker
2025-01-18 15:01:19,896 - INFO - Worker Worker(salt=6200395780, workers=1, host=LAPTOP-2FUAA63D, username=root, pid=31794) was stopped. Shutting down Keep-Alive thread
2025-01-18 15:01:19,897 - INFO - 
===== Luigi Execution Summary =====

Scheduled 8 tasks of which:
* 2 ran successfully:
    - 1 ExtractMarketingData()
    - 1 ExtractSalesData()
* 3 failed:
    - 1 ExtractNewsData()
    - 1 TransformMarketingData()
    - 1 TransformSalesData()
* 3 were left pending, among these:
    * 3 had failed dependencies:
        - 1 LoadData()
        - 1 TransformNewsData()
        - 1 ValidateData()

This progress looks :( because there were failed tasks

===== Luigi Execution Summary =====

2025-01-18 15:06:29,903 - INFO - [pid 34540] Worker Worker(salt=1702516617, workers=1, host=LAPTOP-2FUAA63D, username=root, pid=34540) done      ExtractMarketingData()
2025-01-18 15:06:29,905 - DEBUG - 1 running tasks, waiting for next task to finish
2025-01-18 15:06:29,908 - INFO - Informed scheduler that task   ExtractMarketingData__99914b932b   has status   DONE
2025-01-18 15:06:29,908 - DEBUG - Asking scheduler for work...
2025-01-18 15:06:29,910 - DEBUG - Pending tasks: 7
2025-01-18 15:06:29,910 - INFO - [pid 34540] Worker Worker(salt=1702516617, workers=1, host=LAPTOP-2FUAA63D, username=root, pid=34540) running   ExtractSalesData()
2025-01-18 15:06:31,012 - INFO - [pid 34540] Worker Worker(salt=1702516617, workers=1, host=LAPTOP-2FUAA63D, username=root, pid=34540) done      ExtractSalesData()
2025-01-18 15:06:31,012 - DEBUG - 1 running tasks, waiting for next task to finish
2025-01-18 15:06:31,015 - INFO - Informed scheduler that task   ExtractSalesData__99914b932b   has status   DONE
2025-01-18 15:06:31,015 - DEBUG - Asking scheduler for work...
2025-01-18 15:06:31,016 - DEBUG - Pending tasks: 6
2025-01-18 15:06:31,016 - INFO - [pid 34540] Worker Worker(salt=1702516617, workers=1, host=LAPTOP-2FUAA63D, username=root, pid=34540) running   ExtractNewsData()
2025-01-18 15:07:17,184 - ERROR - [pid 34540] Worker Worker(salt=1702516617, workers=1, host=LAPTOP-2FUAA63D, username=root, pid=34540) failed    ExtractNewsData()
Traceback (most recent call last):
  File "/root/etl_final_task/etl_luigi.py", line 193, in run
    news_created = soup2.find("div", class_ = "text-cnn_grey text-sm mb-6").text.strip()
AttributeError: 'NoneType' object has no attribute 'text'

During handling of the above exception, another exception occurred:

Traceback (most recent call last):
  File "/usr/local/lib/python3.10/dist-packages/luigi/worker.py", line 210, in run
    new_deps = self._run_get_new_deps()
  File "/usr/local/lib/python3.10/dist-packages/luigi/worker.py", line 138, in _run_get_new_deps
    task_gen = self.task.run()
  File "/root/etl_final_task/etl_luigi.py", line 218, in run
    raise Exception(f"There's some error: {e}")
Exception: There's some error: 'NoneType' object has no attribute 'text'
2025-01-18 15:07:17,185 - DEBUG - 1 running tasks, waiting for next task to finish
2025-01-18 15:07:17,190 - INFO - Informed scheduler that task   ExtractNewsData__99914b932b   has status   FAILED
2025-01-18 15:07:17,190 - DEBUG - Asking scheduler for work...
2025-01-18 15:07:17,192 - DEBUG - Pending tasks: 6
2025-01-18 15:07:17,193 - INFO - [pid 34540] Worker Worker(salt=1702516617, workers=1, host=LAPTOP-2FUAA63D, username=root, pid=34540) running   TransformMarketingData()
2025-01-18 15:07:17,652 - ERROR - [pid 34540] Worker Worker(salt=1702516617, workers=1, host=LAPTOP-2FUAA63D, username=root, pid=34540) failed    TransformMarketingData()
Traceback (most recent call last):
  File "/usr/local/lib/python3.10/dist-packages/luigi/worker.py", line 210, in run
    new_deps = self._run_get_new_deps()
  File "/usr/local/lib/python3.10/dist-packages/luigi/worker.py", line 138, in _run_get_new_deps
    task_gen = self.task.run()
  File "/root/etl_final_task/etl_luigi.py", line 339, in run
    availability.append(CONVERT_VALUES1, inplace=True)
  File "/usr/local/lib/python3.10/dist-packages/pandas/core/generic.py", line 6299, in __getattr__
    return object.__getattribute__(self, name)
AttributeError: 'Series' object has no attribute 'append'
2025-01-18 15:07:17,654 - DEBUG - 1 running tasks, waiting for next task to finish
2025-01-18 15:07:17,660 - INFO - Informed scheduler that task   TransformMarketingData__99914b932b   has status   FAILED
2025-01-18 15:07:17,660 - DEBUG - Asking scheduler for work...
2025-01-18 15:07:17,661 - DEBUG - Pending tasks: 6
2025-01-18 15:07:17,662 - INFO - [pid 34540] Worker Worker(salt=1702516617, workers=1, host=LAPTOP-2FUAA63D, username=root, pid=34540) running   TransformSalesData()
2025-01-18 15:07:18,296 - ERROR - [pid 34540] Worker Worker(salt=1702516617, workers=1, host=LAPTOP-2FUAA63D, username=root, pid=34540) failed    TransformSalesData()
Traceback (most recent call last):
  File "/usr/local/lib/python3.10/dist-packages/luigi/worker.py", line 210, in run
    new_deps = self._run_get_new_deps()
  File "/usr/local/lib/python3.10/dist-packages/luigi/worker.py", line 138, in _run_get_new_deps
    task_gen = self.task.run()
  File "/root/etl_final_task/etl_luigi.py", line 504, in run
    sales_data['no_of_ratings'] = sales_data['no_of_ratings'].str.append(r'\D', '', regex=True)
AttributeError: 'StringMethods' object has no attribute 'append'
2025-01-18 15:07:18,301 - DEBUG - 1 running tasks, waiting for next task to finish
2025-01-18 15:07:18,305 - INFO - Informed scheduler that task   TransformSalesData__99914b932b   has status   FAILED
2025-01-18 15:07:18,305 - DEBUG - Asking scheduler for work...
2025-01-18 15:07:18,307 - DEBUG - Done
2025-01-18 15:07:18,307 - DEBUG - There are no more tasks to run at this time
2025-01-18 15:07:18,308 - DEBUG - There are 6 pending tasks possibly being run by other workers
2025-01-18 15:07:18,308 - DEBUG - There are 6 pending tasks unique to this worker
2025-01-18 15:07:18,308 - DEBUG - There are 6 pending tasks last scheduled by this worker
2025-01-18 15:07:18,308 - INFO - Worker Worker(salt=1702516617, workers=1, host=LAPTOP-2FUAA63D, username=root, pid=34540) was stopped. Shutting down Keep-Alive thread
2025-01-18 15:07:18,309 - INFO - 
===== Luigi Execution Summary =====

Scheduled 8 tasks of which:
* 2 ran successfully:
    - 1 ExtractMarketingData()
    - 1 ExtractSalesData()
* 3 failed:
    - 1 ExtractNewsData()
    - 1 TransformMarketingData()
    - 1 TransformSalesData()
* 3 were left pending, among these:
    * 3 had failed dependencies:
        - 1 LoadData()
        - 1 TransformNewsData()
        - 1 ValidateData()

This progress looks :( because there were failed tasks

===== Luigi Execution Summary =====

2025-01-18 15:28:10,148 - INFO - [pid 43579] Worker Worker(salt=202688361, workers=1, host=LAPTOP-2FUAA63D, username=root, pid=43579) done      ExtractMarketingData()
2025-01-18 15:28:10,150 - DEBUG - 1 running tasks, waiting for next task to finish
2025-01-18 15:28:10,153 - INFO - Informed scheduler that task   ExtractMarketingData__99914b932b   has status   DONE
2025-01-18 15:28:10,153 - DEBUG - Asking scheduler for work...
2025-01-18 15:28:10,155 - DEBUG - Pending tasks: 7
2025-01-18 15:28:10,156 - INFO - [pid 43579] Worker Worker(salt=202688361, workers=1, host=LAPTOP-2FUAA63D, username=root, pid=43579) running   ExtractSalesData()
2025-01-18 15:28:11,348 - INFO - [pid 43579] Worker Worker(salt=202688361, workers=1, host=LAPTOP-2FUAA63D, username=root, pid=43579) done      ExtractSalesData()
2025-01-18 15:28:11,349 - DEBUG - 1 running tasks, waiting for next task to finish
2025-01-18 15:28:11,352 - INFO - Informed scheduler that task   ExtractSalesData__99914b932b   has status   DONE
2025-01-18 15:28:11,352 - DEBUG - Asking scheduler for work...
2025-01-18 15:28:11,354 - DEBUG - Pending tasks: 6
2025-01-18 15:28:11,355 - INFO - [pid 43579] Worker Worker(salt=202688361, workers=1, host=LAPTOP-2FUAA63D, username=root, pid=43579) running   ExtractNewsData()
2025-01-18 15:28:24,037 - ERROR - [pid 43579] Worker Worker(salt=202688361, workers=1, host=LAPTOP-2FUAA63D, username=root, pid=43579) failed    ExtractNewsData()
Traceback (most recent call last):
  File "/root/etl_final_task/etl_luigi.py", line 191, in run
    news_created = soup2.find("div", class_ = "text-cnn_grey text-sm mb-6").text.strip()
AttributeError: 'NoneType' object has no attribute 'text'

During handling of the above exception, another exception occurred:

Traceback (most recent call last):
  File "/usr/local/lib/python3.10/dist-packages/luigi/worker.py", line 210, in run
    new_deps = self._run_get_new_deps()
  File "/usr/local/lib/python3.10/dist-packages/luigi/worker.py", line 138, in _run_get_new_deps
    task_gen = self.task.run()
  File "/root/etl_final_task/etl_luigi.py", line 218, in run
    raise Exception(f"There's some error: {e}")
Exception: There's some error: 'NoneType' object has no attribute 'text'
2025-01-18 15:28:24,038 - DEBUG - 1 running tasks, waiting for next task to finish
2025-01-18 15:28:24,042 - INFO - Informed scheduler that task   ExtractNewsData__99914b932b   has status   FAILED
2025-01-18 15:28:24,043 - DEBUG - Asking scheduler for work...
2025-01-18 15:28:24,045 - DEBUG - Pending tasks: 6
2025-01-18 15:28:24,045 - INFO - [pid 43579] Worker Worker(salt=202688361, workers=1, host=LAPTOP-2FUAA63D, username=root, pid=43579) running   TransformMarketingData()
2025-01-18 15:28:24,514 - ERROR - [pid 43579] Worker Worker(salt=202688361, workers=1, host=LAPTOP-2FUAA63D, username=root, pid=43579) failed    TransformMarketingData()
Traceback (most recent call last):
  File "/usr/local/lib/python3.10/dist-packages/luigi/worker.py", line 210, in run
    new_deps = self._run_get_new_deps()
  File "/usr/local/lib/python3.10/dist-packages/luigi/worker.py", line 138, in _run_get_new_deps
    task_gen = self.task.run()
  File "/root/etl_final_task/etl_luigi.py", line 339, in run
    availability.append(CONVERT_VALUES1, inplace=True)
  File "/usr/local/lib/python3.10/dist-packages/pandas/core/generic.py", line 6299, in __getattr__
    return object.__getattribute__(self, name)
AttributeError: 'Series' object has no attribute 'append'
2025-01-18 15:28:24,517 - DEBUG - 1 running tasks, waiting for next task to finish
2025-01-18 15:28:24,521 - INFO - Informed scheduler that task   TransformMarketingData__99914b932b   has status   FAILED
2025-01-18 15:28:24,521 - DEBUG - Asking scheduler for work...
2025-01-18 15:28:24,523 - DEBUG - Pending tasks: 6
2025-01-18 15:28:24,523 - INFO - [pid 43579] Worker Worker(salt=202688361, workers=1, host=LAPTOP-2FUAA63D, username=root, pid=43579) running   TransformSalesData()
2025-01-18 15:28:25,086 - ERROR - [pid 43579] Worker Worker(salt=202688361, workers=1, host=LAPTOP-2FUAA63D, username=root, pid=43579) failed    TransformSalesData()
Traceback (most recent call last):
  File "/usr/local/lib/python3.10/dist-packages/luigi/worker.py", line 210, in run
    new_deps = self._run_get_new_deps()
  File "/usr/local/lib/python3.10/dist-packages/luigi/worker.py", line 138, in _run_get_new_deps
    task_gen = self.task.run()
  File "/root/etl_final_task/etl_luigi.py", line 504, in run
    sales_data['no_of_ratings'] = sales_data['no_of_ratings'].str.append(r'\D', '', regex=True)
AttributeError: 'StringMethods' object has no attribute 'append'
2025-01-18 15:28:25,090 - DEBUG - 1 running tasks, waiting for next task to finish
2025-01-18 15:28:25,095 - INFO - Informed scheduler that task   TransformSalesData__99914b932b   has status   FAILED
2025-01-18 15:28:25,095 - DEBUG - Asking scheduler for work...
2025-01-18 15:28:25,097 - DEBUG - Done
2025-01-18 15:28:25,097 - DEBUG - There are no more tasks to run at this time
2025-01-18 15:28:25,097 - DEBUG - There are 6 pending tasks possibly being run by other workers
2025-01-18 15:28:25,097 - DEBUG - There are 6 pending tasks unique to this worker
2025-01-18 15:28:25,097 - DEBUG - There are 6 pending tasks last scheduled by this worker
2025-01-18 15:28:25,098 - INFO - Worker Worker(salt=202688361, workers=1, host=LAPTOP-2FUAA63D, username=root, pid=43579) was stopped. Shutting down Keep-Alive thread
2025-01-18 15:28:25,099 - INFO - 
===== Luigi Execution Summary =====

Scheduled 8 tasks of which:
* 2 ran successfully:
    - 1 ExtractMarketingData()
    - 1 ExtractSalesData()
* 3 failed:
    - 1 ExtractNewsData()
    - 1 TransformMarketingData()
    - 1 TransformSalesData()
* 3 were left pending, among these:
    * 3 had failed dependencies:
        - 1 LoadData()
        - 1 TransformNewsData()
        - 1 ValidateData()

This progress looks :( because there were failed tasks

===== Luigi Execution Summary =====

2025-01-18 15:32:05,258 - INFO - [pid 45285] Worker Worker(salt=2721548708, workers=1, host=LAPTOP-2FUAA63D, username=root, pid=45285) done      ExtractMarketingData()
2025-01-18 15:32:05,260 - DEBUG - 1 running tasks, waiting for next task to finish
2025-01-18 15:32:05,263 - INFO - Informed scheduler that task   ExtractMarketingData__99914b932b   has status   DONE
2025-01-18 15:32:05,264 - DEBUG - Asking scheduler for work...
2025-01-18 15:32:05,265 - DEBUG - Pending tasks: 7
2025-01-18 15:32:05,266 - INFO - [pid 45285] Worker Worker(salt=2721548708, workers=1, host=LAPTOP-2FUAA63D, username=root, pid=45285) running   ExtractSalesData()
2025-01-18 15:32:06,413 - INFO - [pid 45285] Worker Worker(salt=2721548708, workers=1, host=LAPTOP-2FUAA63D, username=root, pid=45285) done      ExtractSalesData()
2025-01-18 15:32:06,414 - DEBUG - 1 running tasks, waiting for next task to finish
2025-01-18 15:32:06,417 - INFO - Informed scheduler that task   ExtractSalesData__99914b932b   has status   DONE
2025-01-18 15:32:06,417 - DEBUG - Asking scheduler for work...
2025-01-18 15:32:06,419 - DEBUG - Pending tasks: 6
2025-01-18 15:32:06,419 - INFO - [pid 45285] Worker Worker(salt=2721548708, workers=1, host=LAPTOP-2FUAA63D, username=root, pid=45285) running   ExtractNewsData()
2025-01-18 15:32:42,688 - ERROR - [pid 45285] Worker Worker(salt=2721548708, workers=1, host=LAPTOP-2FUAA63D, username=root, pid=45285) failed    ExtractNewsData()
Traceback (most recent call last):
  File "/root/etl_final_task/etl_luigi.py", line 190, in run
    news_created = soup2.find("div", class_ = "text-cnn_grey text-sm mb-4").text.strip()
AttributeError: 'NoneType' object has no attribute 'text'

During handling of the above exception, another exception occurred:

Traceback (most recent call last):
  File "/usr/local/lib/python3.10/dist-packages/luigi/worker.py", line 210, in run
    new_deps = self._run_get_new_deps()
  File "/usr/local/lib/python3.10/dist-packages/luigi/worker.py", line 138, in _run_get_new_deps
    task_gen = self.task.run()
  File "/root/etl_final_task/etl_luigi.py", line 215, in run
    raise Exception(f"There's some error: {e}")
Exception: There's some error: 'NoneType' object has no attribute 'text'
2025-01-18 15:32:42,689 - DEBUG - 1 running tasks, waiting for next task to finish
2025-01-18 15:32:42,695 - INFO - Informed scheduler that task   ExtractNewsData__99914b932b   has status   FAILED
2025-01-18 15:32:42,695 - DEBUG - Asking scheduler for work...
2025-01-18 15:32:42,697 - DEBUG - Pending tasks: 6
2025-01-18 15:32:42,697 - INFO - [pid 45285] Worker Worker(salt=2721548708, workers=1, host=LAPTOP-2FUAA63D, username=root, pid=45285) running   TransformMarketingData()
2025-01-18 15:32:43,143 - ERROR - [pid 45285] Worker Worker(salt=2721548708, workers=1, host=LAPTOP-2FUAA63D, username=root, pid=45285) failed    TransformMarketingData()
Traceback (most recent call last):
  File "/usr/local/lib/python3.10/dist-packages/luigi/worker.py", line 210, in run
    new_deps = self._run_get_new_deps()
  File "/usr/local/lib/python3.10/dist-packages/luigi/worker.py", line 138, in _run_get_new_deps
    task_gen = self.task.run()
  File "/root/etl_final_task/etl_luigi.py", line 336, in run
    availability.append(CONVERT_VALUES1, inplace=True)
  File "/usr/local/lib/python3.10/dist-packages/pandas/core/generic.py", line 6299, in __getattr__
    return object.__getattribute__(self, name)
AttributeError: 'Series' object has no attribute 'append'
2025-01-18 15:32:43,147 - DEBUG - 1 running tasks, waiting for next task to finish
2025-01-18 15:32:43,151 - INFO - Informed scheduler that task   TransformMarketingData__99914b932b   has status   FAILED
2025-01-18 15:32:43,151 - DEBUG - Asking scheduler for work...
2025-01-18 15:32:43,153 - DEBUG - Pending tasks: 6
2025-01-18 15:32:43,154 - INFO - [pid 45285] Worker Worker(salt=2721548708, workers=1, host=LAPTOP-2FUAA63D, username=root, pid=45285) running   TransformSalesData()
2025-01-18 15:32:43,676 - ERROR - [pid 45285] Worker Worker(salt=2721548708, workers=1, host=LAPTOP-2FUAA63D, username=root, pid=45285) failed    TransformSalesData()
Traceback (most recent call last):
  File "/usr/local/lib/python3.10/dist-packages/luigi/worker.py", line 210, in run
    new_deps = self._run_get_new_deps()
  File "/usr/local/lib/python3.10/dist-packages/luigi/worker.py", line 138, in _run_get_new_deps
    task_gen = self.task.run()
  File "/root/etl_final_task/etl_luigi.py", line 501, in run
    sales_data['no_of_ratings'] = sales_data['no_of_ratings'].str.append(r'\D', '', regex=True)
AttributeError: 'StringMethods' object has no attribute 'append'
2025-01-18 15:32:43,680 - DEBUG - 1 running tasks, waiting for next task to finish
2025-01-18 15:32:43,685 - INFO - Informed scheduler that task   TransformSalesData__99914b932b   has status   FAILED
2025-01-18 15:32:43,685 - DEBUG - Asking scheduler for work...
2025-01-18 15:32:43,687 - DEBUG - Done
2025-01-18 15:32:43,687 - DEBUG - There are no more tasks to run at this time
2025-01-18 15:32:43,687 - DEBUG - There are 6 pending tasks possibly being run by other workers
2025-01-18 15:32:43,687 - DEBUG - There are 6 pending tasks unique to this worker
2025-01-18 15:32:43,687 - DEBUG - There are 6 pending tasks last scheduled by this worker
2025-01-18 15:32:43,687 - INFO - Worker Worker(salt=2721548708, workers=1, host=LAPTOP-2FUAA63D, username=root, pid=45285) was stopped. Shutting down Keep-Alive thread
2025-01-18 15:32:43,689 - INFO - 
===== Luigi Execution Summary =====

Scheduled 8 tasks of which:
* 2 ran successfully:
    - 1 ExtractMarketingData()
    - 1 ExtractSalesData()
* 3 failed:
    - 1 ExtractNewsData()
    - 1 TransformMarketingData()
    - 1 TransformSalesData()
* 3 were left pending, among these:
    * 3 had failed dependencies:
        - 1 LoadData()
        - 1 TransformNewsData()
        - 1 ValidateData()

This progress looks :( because there were failed tasks

===== Luigi Execution Summary =====

2025-01-18 15:36:37,101 - ERROR - [pid 47352] Worker Worker(salt=7409713008, workers=1, host=LAPTOP-2FUAA63D, username=root, pid=47352) failed    ExtractNewsData()
Traceback (most recent call last):
  File "/root/etl_final_task/etl_luigi.py", line 166, in run
    get_link = links["url"].loc[idx]
TypeError: list indices must be integers or slices, not str

During handling of the above exception, another exception occurred:

Traceback (most recent call last):
  File "/usr/local/lib/python3.10/dist-packages/luigi/worker.py", line 210, in run
    new_deps = self._run_get_new_deps()
  File "/usr/local/lib/python3.10/dist-packages/luigi/worker.py", line 138, in _run_get_new_deps
    task_gen = self.task.run()
  File "/root/etl_final_task/etl_luigi.py", line 221, in run
    raise Exception("There's some error",e)
Exception: ("There's some error", TypeError('list indices must be integers or slices, not str'))
2025-01-18 15:36:37,102 - DEBUG - 1 running tasks, waiting for next task to finish
2025-01-18 15:36:37,107 - INFO - Informed scheduler that task   ExtractNewsData__99914b932b   has status   FAILED
2025-01-18 15:36:37,108 - DEBUG - Asking scheduler for work...
2025-01-18 15:36:37,110 - DEBUG - Pending tasks: 6
2025-01-18 15:36:37,110 - INFO - [pid 47352] Worker Worker(salt=7409713008, workers=1, host=LAPTOP-2FUAA63D, username=root, pid=47352) running   TransformMarketingData()
2025-01-18 15:36:37,540 - ERROR - [pid 47352] Worker Worker(salt=7409713008, workers=1, host=LAPTOP-2FUAA63D, username=root, pid=47352) failed    TransformMarketingData()
Traceback (most recent call last):
  File "/usr/local/lib/python3.10/dist-packages/luigi/worker.py", line 210, in run
    new_deps = self._run_get_new_deps()
  File "/usr/local/lib/python3.10/dist-packages/luigi/worker.py", line 138, in _run_get_new_deps
    task_gen = self.task.run()
  File "/root/etl_final_task/etl_luigi.py", line 342, in run
    availability.append(CONVERT_VALUES1, inplace=True)
  File "/usr/local/lib/python3.10/dist-packages/pandas/core/generic.py", line 6299, in __getattr__
    return object.__getattribute__(self, name)
AttributeError: 'Series' object has no attribute 'append'
2025-01-18 15:36:37,542 - DEBUG - 1 running tasks, waiting for next task to finish
2025-01-18 15:36:37,546 - INFO - Informed scheduler that task   TransformMarketingData__99914b932b   has status   FAILED
2025-01-18 15:36:37,546 - DEBUG - Asking scheduler for work...
2025-01-18 15:36:37,548 - DEBUG - Pending tasks: 6
2025-01-18 15:36:37,549 - INFO - [pid 47352] Worker Worker(salt=7409713008, workers=1, host=LAPTOP-2FUAA63D, username=root, pid=47352) running   TransformSalesData()
2025-01-18 15:36:37,995 - ERROR - [pid 47352] Worker Worker(salt=7409713008, workers=1, host=LAPTOP-2FUAA63D, username=root, pid=47352) failed    TransformSalesData()
Traceback (most recent call last):
  File "/usr/local/lib/python3.10/dist-packages/luigi/worker.py", line 210, in run
    new_deps = self._run_get_new_deps()
  File "/usr/local/lib/python3.10/dist-packages/luigi/worker.py", line 138, in _run_get_new_deps
    task_gen = self.task.run()
  File "/root/etl_final_task/etl_luigi.py", line 507, in run
    sales_data['no_of_ratings'] = sales_data['no_of_ratings'].str.append(r'\D', '', regex=True)
AttributeError: 'StringMethods' object has no attribute 'append'
2025-01-18 15:36:37,999 - DEBUG - 1 running tasks, waiting for next task to finish
2025-01-18 15:36:38,003 - INFO - Informed scheduler that task   TransformSalesData__99914b932b   has status   FAILED
2025-01-18 15:36:38,003 - DEBUG - Asking scheduler for work...
2025-01-18 15:36:38,005 - DEBUG - Done
2025-01-18 15:36:38,005 - DEBUG - There are no more tasks to run at this time
2025-01-18 15:36:38,006 - DEBUG - There are 6 pending tasks possibly being run by other workers
2025-01-18 15:36:38,006 - DEBUG - There are 6 pending tasks unique to this worker
2025-01-18 15:36:38,006 - DEBUG - There are 6 pending tasks last scheduled by this worker
2025-01-18 15:36:38,006 - INFO - Worker Worker(salt=7409713008, workers=1, host=LAPTOP-2FUAA63D, username=root, pid=47352) was stopped. Shutting down Keep-Alive thread
2025-01-18 15:36:38,007 - INFO - 
===== Luigi Execution Summary =====

Scheduled 8 tasks of which:
* 2 complete ones were encountered:
    - 1 ExtractMarketingData()
    - 1 ExtractSalesData()
* 3 failed:
    - 1 ExtractNewsData()
    - 1 TransformMarketingData()
    - 1 TransformSalesData()
* 3 were left pending, among these:
    * 3 had failed dependencies:
        - 1 LoadData()
        - 1 TransformNewsData()
        - 1 ValidateData()

This progress looks :( because there were failed tasks

===== Luigi Execution Summary =====

2025-01-18 15:44:43,344 - INFO - [pid 50821] Worker Worker(salt=6999709382, workers=1, host=LAPTOP-2FUAA63D, username=root, pid=50821) done      ExtractMarketingData()
2025-01-18 15:44:43,345 - DEBUG - 1 running tasks, waiting for next task to finish
2025-01-18 15:44:43,348 - INFO - Informed scheduler that task   ExtractMarketingData__99914b932b   has status   DONE
2025-01-18 15:44:43,348 - DEBUG - Asking scheduler for work...
2025-01-18 15:44:43,351 - DEBUG - Pending tasks: 7
2025-01-18 15:44:43,351 - INFO - [pid 50821] Worker Worker(salt=6999709382, workers=1, host=LAPTOP-2FUAA63D, username=root, pid=50821) running   ExtractSalesData()
2025-01-18 15:44:44,470 - INFO - [pid 50821] Worker Worker(salt=6999709382, workers=1, host=LAPTOP-2FUAA63D, username=root, pid=50821) done      ExtractSalesData()
2025-01-18 15:44:44,470 - DEBUG - 1 running tasks, waiting for next task to finish
2025-01-18 15:44:44,473 - INFO - Informed scheduler that task   ExtractSalesData__99914b932b   has status   DONE
2025-01-18 15:44:44,473 - DEBUG - Asking scheduler for work...
2025-01-18 15:44:44,475 - DEBUG - Pending tasks: 6
2025-01-18 15:44:44,475 - INFO - [pid 50821] Worker Worker(salt=6999709382, workers=1, host=LAPTOP-2FUAA63D, username=root, pid=50821) running   ExtractNewsData()
2025-01-18 15:45:31,017 - ERROR - [pid 50821] Worker Worker(salt=6999709382, workers=1, host=LAPTOP-2FUAA63D, username=root, pid=50821) failed    ExtractNewsData()
Traceback (most recent call last):
  File "/root/etl_final_task/etl_luigi.py", line 192, in run
    news_created = soup.find("div", class_ = "text-cnn_grey text-sm mb-6").text.strip()
AttributeError: 'NoneType' object has no attribute 'text'

During handling of the above exception, another exception occurred:

Traceback (most recent call last):
  File "/usr/local/lib/python3.10/dist-packages/luigi/worker.py", line 210, in run
    new_deps = self._run_get_new_deps()
  File "/usr/local/lib/python3.10/dist-packages/luigi/worker.py", line 138, in _run_get_new_deps
    task_gen = self.task.run()
  File "/root/etl_final_task/etl_luigi.py", line 222, in run
    raise Exception("There's some error",e)
Exception: ("There's some error", AttributeError("'NoneType' object has no attribute 'text'"))
2025-01-18 15:45:31,018 - DEBUG - 1 running tasks, waiting for next task to finish
2025-01-18 15:45:31,024 - INFO - Informed scheduler that task   ExtractNewsData__99914b932b   has status   FAILED
2025-01-18 15:45:31,025 - DEBUG - Asking scheduler for work...
2025-01-18 15:45:31,027 - DEBUG - Pending tasks: 6
2025-01-18 15:45:31,027 - INFO - [pid 50821] Worker Worker(salt=6999709382, workers=1, host=LAPTOP-2FUAA63D, username=root, pid=50821) running   TransformMarketingData()
2025-01-18 15:45:31,500 - ERROR - [pid 50821] Worker Worker(salt=6999709382, workers=1, host=LAPTOP-2FUAA63D, username=root, pid=50821) failed    TransformMarketingData()
Traceback (most recent call last):
  File "/usr/local/lib/python3.10/dist-packages/luigi/worker.py", line 210, in run
    new_deps = self._run_get_new_deps()
  File "/usr/local/lib/python3.10/dist-packages/luigi/worker.py", line 138, in _run_get_new_deps
    task_gen = self.task.run()
  File "/root/etl_final_task/etl_luigi.py", line 343, in run
    availability.append(CONVERT_VALUES1, inplace=True)
  File "/usr/local/lib/python3.10/dist-packages/pandas/core/generic.py", line 6299, in __getattr__
    return object.__getattribute__(self, name)
AttributeError: 'Series' object has no attribute 'append'
2025-01-18 15:45:31,502 - DEBUG - 1 running tasks, waiting for next task to finish
2025-01-18 15:45:31,506 - INFO - Informed scheduler that task   TransformMarketingData__99914b932b   has status   FAILED
2025-01-18 15:45:31,506 - DEBUG - Asking scheduler for work...
2025-01-18 15:45:31,508 - DEBUG - Pending tasks: 6
2025-01-18 15:45:31,508 - INFO - [pid 50821] Worker Worker(salt=6999709382, workers=1, host=LAPTOP-2FUAA63D, username=root, pid=50821) running   TransformSalesData()
2025-01-18 15:45:32,054 - ERROR - [pid 50821] Worker Worker(salt=6999709382, workers=1, host=LAPTOP-2FUAA63D, username=root, pid=50821) failed    TransformSalesData()
Traceback (most recent call last):
  File "/usr/local/lib/python3.10/dist-packages/luigi/worker.py", line 210, in run
    new_deps = self._run_get_new_deps()
  File "/usr/local/lib/python3.10/dist-packages/luigi/worker.py", line 138, in _run_get_new_deps
    task_gen = self.task.run()
  File "/root/etl_final_task/etl_luigi.py", line 508, in run
    sales_data['no_of_ratings'] = sales_data['no_of_ratings'].str.append(r'\D', '', regex=True)
AttributeError: 'StringMethods' object has no attribute 'append'
2025-01-18 15:45:32,058 - DEBUG - 1 running tasks, waiting for next task to finish
2025-01-18 15:45:32,062 - INFO - Informed scheduler that task   TransformSalesData__99914b932b   has status   FAILED
2025-01-18 15:45:32,063 - DEBUG - Asking scheduler for work...
2025-01-18 15:45:32,065 - DEBUG - Done
2025-01-18 15:45:32,065 - DEBUG - There are no more tasks to run at this time
2025-01-18 15:45:32,065 - DEBUG - There are 6 pending tasks possibly being run by other workers
2025-01-18 15:45:32,065 - DEBUG - There are 6 pending tasks unique to this worker
2025-01-18 15:45:32,065 - DEBUG - There are 6 pending tasks last scheduled by this worker
2025-01-18 15:45:32,065 - INFO - Worker Worker(salt=6999709382, workers=1, host=LAPTOP-2FUAA63D, username=root, pid=50821) was stopped. Shutting down Keep-Alive thread
2025-01-18 15:45:32,066 - INFO - 
===== Luigi Execution Summary =====

Scheduled 8 tasks of which:
* 2 ran successfully:
    - 1 ExtractMarketingData()
    - 1 ExtractSalesData()
* 3 failed:
    - 1 ExtractNewsData()
    - 1 TransformMarketingData()
    - 1 TransformSalesData()
* 3 were left pending, among these:
    * 3 had failed dependencies:
        - 1 LoadData()
        - 1 TransformNewsData()
        - 1 ValidateData()

This progress looks :( because there were failed tasks

===== Luigi Execution Summary =====

2025-01-18 18:51:53,179 - INFO - [pid 6671] Worker Worker(salt=5400420987, workers=1, host=LAPTOP-2FUAA63D, username=root, pid=6671) done      ExtractMarketingData()
2025-01-18 18:51:53,181 - DEBUG - 1 running tasks, waiting for next task to finish
2025-01-18 18:51:53,184 - INFO - Informed scheduler that task   ExtractMarketingData__99914b932b   has status   DONE
2025-01-18 18:51:53,184 - DEBUG - Asking scheduler for work...
2025-01-18 18:51:53,186 - DEBUG - Pending tasks: 7
2025-01-18 18:51:53,186 - INFO - [pid 6671] Worker Worker(salt=5400420987, workers=1, host=LAPTOP-2FUAA63D, username=root, pid=6671) running   ExtractSalesData()
2025-01-18 18:51:54,397 - INFO - [pid 6671] Worker Worker(salt=5400420987, workers=1, host=LAPTOP-2FUAA63D, username=root, pid=6671) done      ExtractSalesData()
2025-01-18 18:51:54,397 - DEBUG - 1 running tasks, waiting for next task to finish
2025-01-18 18:51:54,400 - INFO - Informed scheduler that task   ExtractSalesData__99914b932b   has status   DONE
2025-01-18 18:51:54,400 - DEBUG - Asking scheduler for work...
2025-01-18 18:51:54,403 - DEBUG - Pending tasks: 6
2025-01-18 18:51:54,403 - INFO - [pid 6671] Worker Worker(salt=5400420987, workers=1, host=LAPTOP-2FUAA63D, username=root, pid=6671) running   ExtractNewsData()
2025-01-18 18:54:07,513 - ERROR - [pid 6671] Worker Worker(salt=5400420987, workers=1, host=LAPTOP-2FUAA63D, username=root, pid=6671) failed    ExtractNewsData()
Traceback (most recent call last):
  File "/root/etl_final_task/etl_luigi.py", line 192, in run
    news_created = soup.find("div", class_ = "text-cnn_grey text-sm mb-6").text.strip()
AttributeError: 'NoneType' object has no attribute 'text'

During handling of the above exception, another exception occurred:

Traceback (most recent call last):
  File "/usr/local/lib/python3.10/dist-packages/luigi/worker.py", line 210, in run
    new_deps = self._run_get_new_deps()
  File "/usr/local/lib/python3.10/dist-packages/luigi/worker.py", line 138, in _run_get_new_deps
    task_gen = self.task.run()
  File "/root/etl_final_task/etl_luigi.py", line 222, in run
    raise Exception("There's some error",e)
Exception: ("There's some error", AttributeError("'NoneType' object has no attribute 'text'"))
2025-01-18 18:54:07,514 - DEBUG - 1 running tasks, waiting for next task to finish
2025-01-18 18:54:07,518 - INFO - Informed scheduler that task   ExtractNewsData__99914b932b   has status   FAILED
2025-01-18 18:54:07,519 - DEBUG - Asking scheduler for work...
2025-01-18 18:54:07,520 - DEBUG - Pending tasks: 6
2025-01-18 18:54:07,521 - INFO - [pid 6671] Worker Worker(salt=5400420987, workers=1, host=LAPTOP-2FUAA63D, username=root, pid=6671) running   TransformMarketingData()
2025-01-18 18:54:07,983 - ERROR - [pid 6671] Worker Worker(salt=5400420987, workers=1, host=LAPTOP-2FUAA63D, username=root, pid=6671) failed    TransformMarketingData()
Traceback (most recent call last):
  File "/usr/local/lib/python3.10/dist-packages/luigi/worker.py", line 210, in run
    new_deps = self._run_get_new_deps()
  File "/usr/local/lib/python3.10/dist-packages/luigi/worker.py", line 138, in _run_get_new_deps
    task_gen = self.task.run()
  File "/root/etl_final_task/etl_luigi.py", line 343, in run
    availability.append(CONVERT_VALUES1, inplace=True)
  File "/usr/local/lib/python3.10/dist-packages/pandas/core/generic.py", line 6299, in __getattr__
    return object.__getattribute__(self, name)
AttributeError: 'Series' object has no attribute 'append'
2025-01-18 18:54:07,987 - DEBUG - 1 running tasks, waiting for next task to finish
2025-01-18 18:54:07,991 - INFO - Informed scheduler that task   TransformMarketingData__99914b932b   has status   FAILED
2025-01-18 18:54:07,991 - DEBUG - Asking scheduler for work...
2025-01-18 18:54:07,994 - DEBUG - Pending tasks: 6
2025-01-18 18:54:07,994 - INFO - [pid 6671] Worker Worker(salt=5400420987, workers=1, host=LAPTOP-2FUAA63D, username=root, pid=6671) running   TransformSalesData()
2025-01-18 18:54:08,454 - ERROR - [pid 6671] Worker Worker(salt=5400420987, workers=1, host=LAPTOP-2FUAA63D, username=root, pid=6671) failed    TransformSalesData()
Traceback (most recent call last):
  File "/usr/local/lib/python3.10/dist-packages/luigi/worker.py", line 210, in run
    new_deps = self._run_get_new_deps()
  File "/usr/local/lib/python3.10/dist-packages/luigi/worker.py", line 138, in _run_get_new_deps
    task_gen = self.task.run()
  File "/root/etl_final_task/etl_luigi.py", line 508, in run
    sales_data['no_of_ratings'] = sales_data['no_of_ratings'].str.append(r'\D', '', regex=True)
AttributeError: 'StringMethods' object has no attribute 'append'
2025-01-18 18:54:08,458 - DEBUG - 1 running tasks, waiting for next task to finish
2025-01-18 18:54:08,463 - INFO - Informed scheduler that task   TransformSalesData__99914b932b   has status   FAILED
2025-01-18 18:54:08,463 - DEBUG - Asking scheduler for work...
2025-01-18 18:54:08,465 - DEBUG - Done
2025-01-18 18:54:08,466 - DEBUG - There are no more tasks to run at this time
2025-01-18 18:54:08,466 - DEBUG - There are 6 pending tasks possibly being run by other workers
2025-01-18 18:54:08,466 - DEBUG - There are 6 pending tasks unique to this worker
2025-01-18 18:54:08,466 - DEBUG - There are 6 pending tasks last scheduled by this worker
2025-01-18 18:54:08,466 - INFO - Worker Worker(salt=5400420987, workers=1, host=LAPTOP-2FUAA63D, username=root, pid=6671) was stopped. Shutting down Keep-Alive thread
2025-01-18 18:54:08,467 - INFO - 
===== Luigi Execution Summary =====

Scheduled 8 tasks of which:
* 2 ran successfully:
    - 1 ExtractMarketingData()
    - 1 ExtractSalesData()
* 3 failed:
    - 1 ExtractNewsData()
    - 1 TransformMarketingData()
    - 1 TransformSalesData()
* 3 were left pending, among these:
    * 3 had failed dependencies:
        - 1 LoadData()
        - 1 TransformNewsData()
        - 1 ValidateData()

This progress looks :( because there were failed tasks

===== Luigi Execution Summary =====

2025-01-18 19:03:23,493 - ERROR - [pid 11186] Worker Worker(salt=6107828495, workers=1, host=LAPTOP-2FUAA63D, username=root, pid=11186) failed    ExtractNewsData()
Traceback (most recent call last):
  File "/root/etl_final_task/etl_luigi.py", line 192, in run
    news_created = soup.find("div", class_ = "text-cnn_grey text-sm mb-6").text.strip()
AttributeError: 'NoneType' object has no attribute 'text'

During handling of the above exception, another exception occurred:

Traceback (most recent call last):
  File "/usr/local/lib/python3.10/dist-packages/luigi/worker.py", line 210, in run
    new_deps = self._run_get_new_deps()
  File "/usr/local/lib/python3.10/dist-packages/luigi/worker.py", line 138, in _run_get_new_deps
    task_gen = self.task.run()
  File "/root/etl_final_task/etl_luigi.py", line 222, in run
    raise Exception("There's some error",e)
Exception: ("There's some error", AttributeError("'NoneType' object has no attribute 'text'"))
2025-01-18 19:03:23,494 - DEBUG - 1 running tasks, waiting for next task to finish
2025-01-18 19:03:23,499 - INFO - Informed scheduler that task   ExtractNewsData__99914b932b   has status   FAILED
2025-01-18 19:03:23,500 - DEBUG - Asking scheduler for work...
2025-01-18 19:03:23,502 - DEBUG - Pending tasks: 6
2025-01-18 19:03:23,502 - INFO - [pid 11186] Worker Worker(salt=6107828495, workers=1, host=LAPTOP-2FUAA63D, username=root, pid=11186) running   TransformMarketingData()
2025-01-18 19:03:23,962 - ERROR - [pid 11186] Worker Worker(salt=6107828495, workers=1, host=LAPTOP-2FUAA63D, username=root, pid=11186) failed    TransformMarketingData()
Traceback (most recent call last):
  File "/usr/local/lib/python3.10/dist-packages/luigi/worker.py", line 210, in run
    new_deps = self._run_get_new_deps()
  File "/usr/local/lib/python3.10/dist-packages/luigi/worker.py", line 138, in _run_get_new_deps
    task_gen = self.task.run()
  File "/root/etl_final_task/etl_luigi.py", line 343, in run
    availability.append(CONVERT_VALUES1, inplace=True)
  File "/usr/local/lib/python3.10/dist-packages/pandas/core/generic.py", line 6299, in __getattr__
    return object.__getattribute__(self, name)
AttributeError: 'Series' object has no attribute 'append'
2025-01-18 19:03:23,964 - DEBUG - 1 running tasks, waiting for next task to finish
2025-01-18 19:03:23,969 - INFO - Informed scheduler that task   TransformMarketingData__99914b932b   has status   FAILED
2025-01-18 19:03:23,969 - DEBUG - Asking scheduler for work...
2025-01-18 19:03:23,971 - DEBUG - Pending tasks: 6
2025-01-18 19:03:23,971 - INFO - [pid 11186] Worker Worker(salt=6107828495, workers=1, host=LAPTOP-2FUAA63D, username=root, pid=11186) running   TransformSalesData()
2025-01-18 19:03:24,583 - ERROR - [pid 11186] Worker Worker(salt=6107828495, workers=1, host=LAPTOP-2FUAA63D, username=root, pid=11186) failed    TransformSalesData()
Traceback (most recent call last):
  File "/usr/local/lib/python3.10/dist-packages/luigi/worker.py", line 210, in run
    new_deps = self._run_get_new_deps()
  File "/usr/local/lib/python3.10/dist-packages/luigi/worker.py", line 138, in _run_get_new_deps
    task_gen = self.task.run()
  File "/root/etl_final_task/etl_luigi.py", line 508, in run
    sales_data['no_of_ratings'] = sales_data['no_of_ratings'].str.append(r'\D', '', regex=True)
AttributeError: 'StringMethods' object has no attribute 'append'
2025-01-18 19:03:24,587 - DEBUG - 1 running tasks, waiting for next task to finish
2025-01-18 19:03:24,591 - INFO - Informed scheduler that task   TransformSalesData__99914b932b   has status   FAILED
2025-01-18 19:03:24,591 - DEBUG - Asking scheduler for work...
2025-01-18 19:03:24,593 - DEBUG - Done
2025-01-18 19:03:24,593 - DEBUG - There are no more tasks to run at this time
2025-01-18 19:03:24,593 - DEBUG - There are 6 pending tasks possibly being run by other workers
2025-01-18 19:03:24,593 - DEBUG - There are 6 pending tasks unique to this worker
2025-01-18 19:03:24,593 - DEBUG - There are 6 pending tasks last scheduled by this worker
2025-01-18 19:03:24,594 - INFO - Worker Worker(salt=6107828495, workers=1, host=LAPTOP-2FUAA63D, username=root, pid=11186) was stopped. Shutting down Keep-Alive thread
2025-01-18 19:03:24,595 - INFO - 
===== Luigi Execution Summary =====

Scheduled 8 tasks of which:
* 2 complete ones were encountered:
    - 1 ExtractMarketingData()
    - 1 ExtractSalesData()
* 3 failed:
    - 1 ExtractNewsData()
    - 1 TransformMarketingData()
    - 1 TransformSalesData()
* 3 were left pending, among these:
    * 3 had failed dependencies:
        - 1 LoadData()
        - 1 TransformNewsData()
        - 1 ValidateData()

This progress looks :( because there were failed tasks

===== Luigi Execution Summary =====

2025-01-18 20:07:27,920 - INFO - [pid 41811] Worker Worker(salt=8838904883, workers=1, host=LAPTOP-2FUAA63D, username=root, pid=41811) done      ExtractMarketingData()
2025-01-18 20:07:27,923 - DEBUG - 1 running tasks, waiting for next task to finish
2025-01-18 20:07:27,925 - INFO - Informed scheduler that task   ExtractMarketingData__99914b932b   has status   DONE
2025-01-18 20:07:27,925 - DEBUG - Asking scheduler for work...
2025-01-18 20:07:27,927 - DEBUG - Pending tasks: 7
2025-01-18 20:07:27,927 - INFO - [pid 41811] Worker Worker(salt=8838904883, workers=1, host=LAPTOP-2FUAA63D, username=root, pid=41811) running   ExtractSalesData()
2025-01-18 20:07:29,164 - INFO - [pid 41811] Worker Worker(salt=8838904883, workers=1, host=LAPTOP-2FUAA63D, username=root, pid=41811) done      ExtractSalesData()
2025-01-18 20:07:29,164 - DEBUG - 1 running tasks, waiting for next task to finish
2025-01-18 20:07:29,167 - INFO - Informed scheduler that task   ExtractSalesData__99914b932b   has status   DONE
2025-01-18 20:07:29,167 - DEBUG - Asking scheduler for work...
2025-01-18 20:07:29,169 - DEBUG - Pending tasks: 6
2025-01-18 20:07:29,169 - INFO - [pid 41811] Worker Worker(salt=8838904883, workers=1, host=LAPTOP-2FUAA63D, username=root, pid=41811) running   ExtractNewsData()
2025-01-18 20:13:02,361 - INFO - [pid 41811] Worker Worker(salt=8838904883, workers=1, host=LAPTOP-2FUAA63D, username=root, pid=41811) done      ExtractNewsData()
2025-01-18 20:13:02,361 - DEBUG - 1 running tasks, waiting for next task to finish
2025-01-18 20:13:02,364 - INFO - Informed scheduler that task   ExtractNewsData__99914b932b   has status   DONE
2025-01-18 20:13:02,364 - DEBUG - Asking scheduler for work...
2025-01-18 20:13:02,366 - DEBUG - Pending tasks: 5
2025-01-18 20:13:02,366 - INFO - [pid 41811] Worker Worker(salt=8838904883, workers=1, host=LAPTOP-2FUAA63D, username=root, pid=41811) running   ValidateData()
2025-01-18 20:13:03,150 - INFO - [pid 41811] Worker Worker(salt=8838904883, workers=1, host=LAPTOP-2FUAA63D, username=root, pid=41811) done      ValidateData()
2025-01-18 20:13:03,151 - DEBUG - 1 running tasks, waiting for next task to finish
2025-01-18 20:13:03,154 - INFO - Informed scheduler that task   ValidateData__99914b932b   has status   DONE
2025-01-18 20:13:03,154 - DEBUG - Asking scheduler for work...
2025-01-18 20:13:03,156 - DEBUG - Pending tasks: 4
2025-01-18 20:13:03,156 - INFO - [pid 41811] Worker Worker(salt=8838904883, workers=1, host=LAPTOP-2FUAA63D, username=root, pid=41811) running   TransformMarketingData()
2025-01-18 20:13:03,539 - ERROR - [pid 41811] Worker Worker(salt=8838904883, workers=1, host=LAPTOP-2FUAA63D, username=root, pid=41811) failed    TransformMarketingData()
Traceback (most recent call last):
  File "/usr/local/lib/python3.10/dist-packages/luigi/worker.py", line 210, in run
    new_deps = self._run_get_new_deps()
  File "/usr/local/lib/python3.10/dist-packages/luigi/worker.py", line 138, in _run_get_new_deps
    task_gen = self.task.run()
  File "/root/etl_final_task/etl_luigi.py", line 457, in run
    availability.append(CONVERT_VALUES1, inplace=True)
  File "/usr/local/lib/python3.10/dist-packages/pandas/core/generic.py", line 6299, in __getattr__
    return object.__getattribute__(self, name)
AttributeError: 'Series' object has no attribute 'append'
2025-01-18 20:13:03,544 - DEBUG - 1 running tasks, waiting for next task to finish
2025-01-18 20:13:03,548 - INFO - Informed scheduler that task   TransformMarketingData__99914b932b   has status   FAILED
2025-01-18 20:13:03,548 - DEBUG - Asking scheduler for work...
2025-01-18 20:13:03,550 - DEBUG - Pending tasks: 4
2025-01-18 20:13:03,550 - INFO - [pid 41811] Worker Worker(salt=8838904883, workers=1, host=LAPTOP-2FUAA63D, username=root, pid=41811) running   TransformSalesData()
2025-01-18 20:13:04,017 - ERROR - [pid 41811] Worker Worker(salt=8838904883, workers=1, host=LAPTOP-2FUAA63D, username=root, pid=41811) failed    TransformSalesData()
Traceback (most recent call last):
  File "/usr/local/lib/python3.10/dist-packages/luigi/worker.py", line 210, in run
    new_deps = self._run_get_new_deps()
  File "/usr/local/lib/python3.10/dist-packages/luigi/worker.py", line 138, in _run_get_new_deps
    task_gen = self.task.run()
  File "/root/etl_final_task/etl_luigi.py", line 622, in run
    sales_data['no_of_ratings'] = sales_data['no_of_ratings'].str.append(r'\D', '', regex=True)
AttributeError: 'StringMethods' object has no attribute 'append'
2025-01-18 20:13:04,021 - DEBUG - 1 running tasks, waiting for next task to finish
2025-01-18 20:13:04,025 - INFO - Informed scheduler that task   TransformSalesData__99914b932b   has status   FAILED
2025-01-18 20:13:04,025 - DEBUG - Asking scheduler for work...
2025-01-18 20:13:04,027 - DEBUG - Pending tasks: 4
2025-01-18 20:13:04,027 - INFO - [pid 41811] Worker Worker(salt=8838904883, workers=1, host=LAPTOP-2FUAA63D, username=root, pid=41811) running   TransformNewsData()
2025-01-18 20:13:04,031 - ERROR - [pid 41811] Worker Worker(salt=8838904883, workers=1, host=LAPTOP-2FUAA63D, username=root, pid=41811) failed    TransformNewsData()
Traceback (most recent call last):
  File "/usr/local/lib/python3.10/dist-packages/luigi/worker.py", line 210, in run
    new_deps = self._run_get_new_deps()
  File "/usr/local/lib/python3.10/dist-packages/luigi/worker.py", line 138, in _run_get_new_deps
    task_gen = self.task.run()
  File "/root/etl_final_task/etl_luigi.py", line 722, in run
    news_data["article"] = news_data["article"].str.append("\xa0", " ")
AttributeError: 'StringMethods' object has no attribute 'append'
2025-01-18 20:13:04,031 - DEBUG - 1 running tasks, waiting for next task to finish
2025-01-18 20:13:04,035 - INFO - Informed scheduler that task   TransformNewsData__99914b932b   has status   FAILED
2025-01-18 20:13:04,035 - DEBUG - Asking scheduler for work...
2025-01-18 20:13:04,037 - DEBUG - Done
2025-01-18 20:13:04,037 - DEBUG - There are no more tasks to run at this time
2025-01-18 20:13:04,037 - DEBUG - There are 4 pending tasks possibly being run by other workers
2025-01-18 20:13:04,037 - DEBUG - There are 4 pending tasks unique to this worker
2025-01-18 20:13:04,038 - DEBUG - There are 4 pending tasks last scheduled by this worker
2025-01-18 20:13:04,038 - INFO - Worker Worker(salt=8838904883, workers=1, host=LAPTOP-2FUAA63D, username=root, pid=41811) was stopped. Shutting down Keep-Alive thread
2025-01-18 20:13:04,039 - INFO - 
===== Luigi Execution Summary =====

Scheduled 8 tasks of which:
* 4 ran successfully:
    - 1 ExtractMarketingData()
    - 1 ExtractNewsData()
    - 1 ExtractSalesData()
    - 1 ValidateData()
* 3 failed:
    - 1 TransformMarketingData()
    - 1 TransformNewsData()
    - 1 TransformSalesData()
* 1 were left pending, among these:
    * 1 had failed dependencies:
        - 1 LoadData()

This progress looks :( because there were failed tasks

===== Luigi Execution Summary =====

2025-01-19 05:59:58,484 - INFO - [pid 6824] Worker Worker(salt=2658791536, workers=1, host=LAPTOP-2FUAA63D, username=root, pid=6824) done      ExtractMarketingData()
2025-01-19 05:59:58,485 - DEBUG - 1 running tasks, waiting for next task to finish
2025-01-19 05:59:58,488 - INFO - Informed scheduler that task   ExtractMarketingData__99914b932b   has status   DONE
2025-01-19 05:59:58,488 - DEBUG - Asking scheduler for work...
2025-01-19 05:59:58,490 - DEBUG - Pending tasks: 7
2025-01-19 05:59:58,490 - INFO - [pid 6824] Worker Worker(salt=2658791536, workers=1, host=LAPTOP-2FUAA63D, username=root, pid=6824) running   ExtractSalesData()
2025-01-19 05:59:59,706 - INFO - [pid 6824] Worker Worker(salt=2658791536, workers=1, host=LAPTOP-2FUAA63D, username=root, pid=6824) done      ExtractSalesData()
2025-01-19 05:59:59,707 - DEBUG - 1 running tasks, waiting for next task to finish
2025-01-19 05:59:59,710 - INFO - Informed scheduler that task   ExtractSalesData__99914b932b   has status   DONE
2025-01-19 05:59:59,710 - DEBUG - Asking scheduler for work...
2025-01-19 05:59:59,713 - DEBUG - Pending tasks: 6
2025-01-19 05:59:59,713 - INFO - [pid 6824] Worker Worker(salt=2658791536, workers=1, host=LAPTOP-2FUAA63D, username=root, pid=6824) running   ExtractNewsData()
2025-01-19 06:02:15,571 - INFO - [pid 6824] Worker Worker(salt=2658791536, workers=1, host=LAPTOP-2FUAA63D, username=root, pid=6824) done      ExtractNewsData()
2025-01-19 06:02:15,572 - DEBUG - 1 running tasks, waiting for next task to finish
2025-01-19 06:02:15,574 - INFO - Informed scheduler that task   ExtractNewsData__99914b932b   has status   DONE
2025-01-19 06:02:15,575 - DEBUG - Asking scheduler for work...
2025-01-19 06:02:15,576 - DEBUG - Pending tasks: 5
2025-01-19 06:02:15,577 - INFO - [pid 6824] Worker Worker(salt=2658791536, workers=1, host=LAPTOP-2FUAA63D, username=root, pid=6824) running   ValidateData()
2025-01-19 06:02:16,348 - INFO - [pid 6824] Worker Worker(salt=2658791536, workers=1, host=LAPTOP-2FUAA63D, username=root, pid=6824) done      ValidateData()
2025-01-19 06:02:16,348 - DEBUG - 1 running tasks, waiting for next task to finish
2025-01-19 06:02:16,351 - INFO - Informed scheduler that task   ValidateData__99914b932b   has status   DONE
2025-01-19 06:02:16,351 - DEBUG - Asking scheduler for work...
2025-01-19 06:02:16,353 - DEBUG - Pending tasks: 4
2025-01-19 06:02:16,353 - INFO - [pid 6824] Worker Worker(salt=2658791536, workers=1, host=LAPTOP-2FUAA63D, username=root, pid=6824) running   TransformMarketingData()
2025-01-19 06:02:16,765 - ERROR - [pid 6824] Worker Worker(salt=2658791536, workers=1, host=LAPTOP-2FUAA63D, username=root, pid=6824) failed    TransformMarketingData()
Traceback (most recent call last):
  File "/usr/local/lib/python3.10/dist-packages/luigi/worker.py", line 210, in run
    new_deps = self._run_get_new_deps()
  File "/usr/local/lib/python3.10/dist-packages/luigi/worker.py", line 138, in _run_get_new_deps
    task_gen = self.task.run()
  File "/root/etl_final_task/etl_luigi.py", line 459, in run
    availability.append(CONVERT_VALUES1, inplace=True)
  File "/usr/local/lib/python3.10/dist-packages/pandas/core/generic.py", line 6299, in __getattr__
    return object.__getattribute__(self, name)
AttributeError: 'Series' object has no attribute 'append'
2025-01-19 06:02:16,769 - DEBUG - 1 running tasks, waiting for next task to finish
2025-01-19 06:02:16,773 - INFO - Informed scheduler that task   TransformMarketingData__99914b932b   has status   FAILED
2025-01-19 06:02:16,773 - DEBUG - Asking scheduler for work...
2025-01-19 06:02:16,775 - DEBUG - Pending tasks: 4
2025-01-19 06:02:16,775 - INFO - [pid 6824] Worker Worker(salt=2658791536, workers=1, host=LAPTOP-2FUAA63D, username=root, pid=6824) running   TransformSalesData()
2025-01-19 06:02:17,231 - ERROR - [pid 6824] Worker Worker(salt=2658791536, workers=1, host=LAPTOP-2FUAA63D, username=root, pid=6824) failed    TransformSalesData()
Traceback (most recent call last):
  File "/usr/local/lib/python3.10/dist-packages/luigi/worker.py", line 210, in run
    new_deps = self._run_get_new_deps()
  File "/usr/local/lib/python3.10/dist-packages/luigi/worker.py", line 138, in _run_get_new_deps
    task_gen = self.task.run()
  File "/root/etl_final_task/etl_luigi.py", line 624, in run
    sales_data['no_of_ratings'] = sales_data['no_of_ratings'].str.append(r'\D', '', regex=True)
AttributeError: 'StringMethods' object has no attribute 'append'
2025-01-19 06:02:17,235 - DEBUG - 1 running tasks, waiting for next task to finish
2025-01-19 06:02:17,239 - INFO - Informed scheduler that task   TransformSalesData__99914b932b   has status   FAILED
2025-01-19 06:02:17,239 - DEBUG - Asking scheduler for work...
2025-01-19 06:02:17,240 - DEBUG - Pending tasks: 4
2025-01-19 06:02:17,241 - INFO - [pid 6824] Worker Worker(salt=2658791536, workers=1, host=LAPTOP-2FUAA63D, username=root, pid=6824) running   TransformNewsData()
2025-01-19 06:02:17,243 - ERROR - [pid 6824] Worker Worker(salt=2658791536, workers=1, host=LAPTOP-2FUAA63D, username=root, pid=6824) failed    TransformNewsData()
Traceback (most recent call last):
  File "/usr/local/lib/python3.10/dist-packages/luigi/worker.py", line 210, in run
    new_deps = self._run_get_new_deps()
  File "/usr/local/lib/python3.10/dist-packages/luigi/worker.py", line 138, in _run_get_new_deps
    task_gen = self.task.run()
  File "/root/etl_final_task/etl_luigi.py", line 724, in run
    news_data["article"] = news_data["article"].str.append("\xa0", " ")
AttributeError: 'StringMethods' object has no attribute 'append'
2025-01-19 06:02:17,244 - DEBUG - 1 running tasks, waiting for next task to finish
2025-01-19 06:02:17,248 - INFO - Informed scheduler that task   TransformNewsData__99914b932b   has status   FAILED
2025-01-19 06:02:17,248 - DEBUG - Asking scheduler for work...
2025-01-19 06:02:17,250 - DEBUG - Done
2025-01-19 06:02:17,250 - DEBUG - There are no more tasks to run at this time
2025-01-19 06:02:17,250 - DEBUG - There are 4 pending tasks possibly being run by other workers
2025-01-19 06:02:17,250 - DEBUG - There are 4 pending tasks unique to this worker
2025-01-19 06:02:17,250 - DEBUG - There are 4 pending tasks last scheduled by this worker
2025-01-19 06:02:17,250 - INFO - Worker Worker(salt=2658791536, workers=1, host=LAPTOP-2FUAA63D, username=root, pid=6824) was stopped. Shutting down Keep-Alive thread
2025-01-19 06:02:17,252 - INFO - 
===== Luigi Execution Summary =====

Scheduled 8 tasks of which:
* 4 ran successfully:
    - 1 ExtractMarketingData()
    - 1 ExtractNewsData()
    - 1 ExtractSalesData()
    - 1 ValidateData()
* 3 failed:
    - 1 TransformMarketingData()
    - 1 TransformNewsData()
    - 1 TransformSalesData()
* 1 were left pending, among these:
    * 1 had failed dependencies:
        - 1 LoadData()

This progress looks :( because there were failed tasks

===== Luigi Execution Summary =====

2025-01-19 06:11:27,438 - INFO - [pid 12240] Worker Worker(salt=1702464720, workers=1, host=LAPTOP-2FUAA63D, username=root, pid=12240) done      ExtractMarketingData()
2025-01-19 06:11:27,438 - DEBUG - 1 running tasks, waiting for next task to finish
2025-01-19 06:11:27,441 - INFO - Informed scheduler that task   ExtractMarketingData__99914b932b   has status   DONE
2025-01-19 06:11:27,442 - DEBUG - Asking scheduler for work...
2025-01-19 06:11:27,443 - DEBUG - Pending tasks: 7
2025-01-19 06:11:27,443 - INFO - [pid 12240] Worker Worker(salt=1702464720, workers=1, host=LAPTOP-2FUAA63D, username=root, pid=12240) running   ExtractSalesData()
2025-01-19 06:11:28,569 - INFO - [pid 12240] Worker Worker(salt=1702464720, workers=1, host=LAPTOP-2FUAA63D, username=root, pid=12240) done      ExtractSalesData()
2025-01-19 06:11:28,569 - DEBUG - 1 running tasks, waiting for next task to finish
2025-01-19 06:11:28,572 - INFO - Informed scheduler that task   ExtractSalesData__99914b932b   has status   DONE
2025-01-19 06:11:28,572 - DEBUG - Asking scheduler for work...
2025-01-19 06:11:28,574 - DEBUG - Pending tasks: 6
2025-01-19 06:11:28,575 - INFO - [pid 12240] Worker Worker(salt=1702464720, workers=1, host=LAPTOP-2FUAA63D, username=root, pid=12240) running   ExtractNewsData()
2025-01-19 06:13:09,520 - INFO - [pid 12240] Worker Worker(salt=1702464720, workers=1, host=LAPTOP-2FUAA63D, username=root, pid=12240) done      ExtractNewsData()
2025-01-19 06:13:09,520 - DEBUG - 1 running tasks, waiting for next task to finish
2025-01-19 06:13:09,523 - INFO - Informed scheduler that task   ExtractNewsData__99914b932b   has status   DONE
2025-01-19 06:13:09,523 - DEBUG - Asking scheduler for work...
2025-01-19 06:13:09,525 - DEBUG - Pending tasks: 5
2025-01-19 06:13:09,525 - INFO - [pid 12240] Worker Worker(salt=1702464720, workers=1, host=LAPTOP-2FUAA63D, username=root, pid=12240) running   ValidateData()
2025-01-19 06:13:10,280 - INFO - [pid 12240] Worker Worker(salt=1702464720, workers=1, host=LAPTOP-2FUAA63D, username=root, pid=12240) done      ValidateData()
2025-01-19 06:13:10,280 - DEBUG - 1 running tasks, waiting for next task to finish
2025-01-19 06:13:10,283 - INFO - Informed scheduler that task   ValidateData__99914b932b   has status   DONE
2025-01-19 06:13:10,284 - DEBUG - Asking scheduler for work...
2025-01-19 06:13:10,286 - DEBUG - Pending tasks: 4
2025-01-19 06:13:10,286 - INFO - [pid 12240] Worker Worker(salt=1702464720, workers=1, host=LAPTOP-2FUAA63D, username=root, pid=12240) running   TransformMarketingData()
2025-01-19 06:13:10,657 - ERROR - [pid 12240] Worker Worker(salt=1702464720, workers=1, host=LAPTOP-2FUAA63D, username=root, pid=12240) failed    TransformMarketingData()
Traceback (most recent call last):
  File "/usr/local/lib/python3.10/dist-packages/luigi/worker.py", line 210, in run
    new_deps = self._run_get_new_deps()
  File "/usr/local/lib/python3.10/dist-packages/luigi/worker.py", line 138, in _run_get_new_deps
    task_gen = self.task.run()
  File "/root/etl_final_task/etl_luigi.py", line 479, in run
    marketing_data['main_category'].append('electronics', inplace=True)
  File "/usr/local/lib/python3.10/dist-packages/pandas/core/generic.py", line 6299, in __getattr__
    return object.__getattribute__(self, name)
AttributeError: 'Series' object has no attribute 'append'
2025-01-19 06:13:10,659 - DEBUG - 1 running tasks, waiting for next task to finish
2025-01-19 06:13:10,664 - INFO - Informed scheduler that task   TransformMarketingData__99914b932b   has status   FAILED
2025-01-19 06:13:10,664 - DEBUG - Asking scheduler for work...
2025-01-19 06:13:10,666 - DEBUG - Pending tasks: 4
2025-01-19 06:13:10,666 - INFO - [pid 12240] Worker Worker(salt=1702464720, workers=1, host=LAPTOP-2FUAA63D, username=root, pid=12240) running   TransformSalesData()
2025-01-19 06:13:11,147 - ERROR - [pid 12240] Worker Worker(salt=1702464720, workers=1, host=LAPTOP-2FUAA63D, username=root, pid=12240) failed    TransformSalesData()
Traceback (most recent call last):
  File "/usr/local/lib/python3.10/dist-packages/luigi/worker.py", line 210, in run
    new_deps = self._run_get_new_deps()
  File "/usr/local/lib/python3.10/dist-packages/luigi/worker.py", line 138, in _run_get_new_deps
    task_gen = self.task.run()
  File "/root/etl_final_task/etl_luigi.py", line 634, in run
    sales_data['actual_price'] = sales_data['actual_price'].str.append(r'\D', '', regex=True)
AttributeError: 'StringMethods' object has no attribute 'append'
2025-01-19 06:13:11,151 - DEBUG - 1 running tasks, waiting for next task to finish
2025-01-19 06:13:11,155 - INFO - Informed scheduler that task   TransformSalesData__99914b932b   has status   FAILED
2025-01-19 06:13:11,156 - DEBUG - Asking scheduler for work...
2025-01-19 06:13:11,159 - DEBUG - Pending tasks: 4
2025-01-19 06:13:11,159 - INFO - [pid 12240] Worker Worker(salt=1702464720, workers=1, host=LAPTOP-2FUAA63D, username=root, pid=12240) running   TransformNewsData()
2025-01-19 06:13:11,175 - INFO - [pid 12240] Worker Worker(salt=1702464720, workers=1, host=LAPTOP-2FUAA63D, username=root, pid=12240) done      TransformNewsData()
2025-01-19 06:13:11,175 - DEBUG - 1 running tasks, waiting for next task to finish
2025-01-19 06:13:11,178 - INFO - Informed scheduler that task   TransformNewsData__99914b932b   has status   DONE
2025-01-19 06:13:11,178 - DEBUG - Asking scheduler for work...
2025-01-19 06:13:11,181 - DEBUG - Done
2025-01-19 06:13:11,181 - DEBUG - There are no more tasks to run at this time
2025-01-19 06:13:11,181 - DEBUG - There are 3 pending tasks possibly being run by other workers
2025-01-19 06:13:11,181 - DEBUG - There are 3 pending tasks unique to this worker
2025-01-19 06:13:11,181 - DEBUG - There are 3 pending tasks last scheduled by this worker
2025-01-19 06:13:11,182 - INFO - Worker Worker(salt=1702464720, workers=1, host=LAPTOP-2FUAA63D, username=root, pid=12240) was stopped. Shutting down Keep-Alive thread
2025-01-19 06:13:11,183 - INFO - 
===== Luigi Execution Summary =====

Scheduled 8 tasks of which:
* 5 ran successfully:
    - 1 ExtractMarketingData()
    - 1 ExtractNewsData()
    - 1 ExtractSalesData()
    - 1 TransformNewsData()
    - 1 ValidateData()
* 2 failed:
    - 1 TransformMarketingData()
    - 1 TransformSalesData()
* 1 were left pending, among these:
    * 1 had failed dependencies:
        - 1 LoadData()

This progress looks :( because there were failed tasks

===== Luigi Execution Summary =====

2025-01-19 06:17:10,087 - INFO - [pid 15010] Worker Worker(salt=2126234251, workers=1, host=LAPTOP-2FUAA63D, username=root, pid=15010) done      ExtractMarketingData()
2025-01-19 06:17:10,088 - DEBUG - 1 running tasks, waiting for next task to finish
2025-01-19 06:17:10,090 - INFO - Informed scheduler that task   ExtractMarketingData__99914b932b   has status   DONE
2025-01-19 06:17:10,091 - DEBUG - Asking scheduler for work...
2025-01-19 06:17:10,093 - DEBUG - Pending tasks: 7
2025-01-19 06:17:10,093 - INFO - [pid 15010] Worker Worker(salt=2126234251, workers=1, host=LAPTOP-2FUAA63D, username=root, pid=15010) running   ExtractSalesData()
2025-01-19 06:17:11,160 - INFO - [pid 15010] Worker Worker(salt=2126234251, workers=1, host=LAPTOP-2FUAA63D, username=root, pid=15010) done      ExtractSalesData()
2025-01-19 06:17:11,160 - DEBUG - 1 running tasks, waiting for next task to finish
2025-01-19 06:17:11,163 - INFO - Informed scheduler that task   ExtractSalesData__99914b932b   has status   DONE
2025-01-19 06:17:11,163 - DEBUG - Asking scheduler for work...
2025-01-19 06:17:11,165 - DEBUG - Pending tasks: 6
2025-01-19 06:17:11,166 - INFO - [pid 15010] Worker Worker(salt=2126234251, workers=1, host=LAPTOP-2FUAA63D, username=root, pid=15010) running   ExtractNewsData()
2025-01-19 06:19:03,874 - INFO - [pid 15010] Worker Worker(salt=2126234251, workers=1, host=LAPTOP-2FUAA63D, username=root, pid=15010) done      ExtractNewsData()
2025-01-19 06:19:03,874 - DEBUG - 1 running tasks, waiting for next task to finish
2025-01-19 06:19:03,877 - INFO - Informed scheduler that task   ExtractNewsData__99914b932b   has status   DONE
2025-01-19 06:19:03,877 - DEBUG - Asking scheduler for work...
2025-01-19 06:19:03,879 - DEBUG - Pending tasks: 5
2025-01-19 06:19:03,879 - INFO - [pid 15010] Worker Worker(salt=2126234251, workers=1, host=LAPTOP-2FUAA63D, username=root, pid=15010) running   ValidateData()
2025-01-19 06:19:04,703 - INFO - [pid 15010] Worker Worker(salt=2126234251, workers=1, host=LAPTOP-2FUAA63D, username=root, pid=15010) done      ValidateData()
2025-01-19 06:19:04,704 - DEBUG - 1 running tasks, waiting for next task to finish
2025-01-19 06:19:04,707 - INFO - Informed scheduler that task   ValidateData__99914b932b   has status   DONE
2025-01-19 06:19:04,707 - DEBUG - Asking scheduler for work...
2025-01-19 06:19:04,709 - DEBUG - Pending tasks: 4
2025-01-19 06:19:04,710 - INFO - [pid 15010] Worker Worker(salt=2126234251, workers=1, host=LAPTOP-2FUAA63D, username=root, pid=15010) running   TransformMarketingData()
2025-01-19 06:19:08,655 - INFO - [pid 15010] Worker Worker(salt=2126234251, workers=1, host=LAPTOP-2FUAA63D, username=root, pid=15010) done      TransformMarketingData()
2025-01-19 06:19:08,655 - DEBUG - 1 running tasks, waiting for next task to finish
2025-01-19 06:19:08,658 - INFO - Informed scheduler that task   TransformMarketingData__99914b932b   has status   DONE
2025-01-19 06:19:08,658 - DEBUG - Asking scheduler for work...
2025-01-19 06:19:08,661 - DEBUG - Pending tasks: 3
2025-01-19 06:19:08,661 - INFO - [pid 15010] Worker Worker(salt=2126234251, workers=1, host=LAPTOP-2FUAA63D, username=root, pid=15010) running   TransformSalesData()
2025-01-19 06:19:09,924 - INFO - [pid 15010] Worker Worker(salt=2126234251, workers=1, host=LAPTOP-2FUAA63D, username=root, pid=15010) done      TransformSalesData()
2025-01-19 06:19:09,924 - DEBUG - 1 running tasks, waiting for next task to finish
2025-01-19 06:19:09,927 - INFO - Informed scheduler that task   TransformSalesData__99914b932b   has status   DONE
2025-01-19 06:19:09,927 - DEBUG - Asking scheduler for work...
2025-01-19 06:19:09,930 - DEBUG - Pending tasks: 2
2025-01-19 06:19:09,930 - INFO - [pid 15010] Worker Worker(salt=2126234251, workers=1, host=LAPTOP-2FUAA63D, username=root, pid=15010) running   TransformNewsData()
2025-01-19 06:19:09,941 - INFO - [pid 15010] Worker Worker(salt=2126234251, workers=1, host=LAPTOP-2FUAA63D, username=root, pid=15010) done      TransformNewsData()
2025-01-19 06:19:09,942 - DEBUG - 1 running tasks, waiting for next task to finish
2025-01-19 06:19:09,945 - INFO - Informed scheduler that task   TransformNewsData__99914b932b   has status   DONE
2025-01-19 06:19:09,945 - DEBUG - Asking scheduler for work...
2025-01-19 06:19:09,948 - DEBUG - Pending tasks: 1
2025-01-19 06:19:09,948 - INFO - [pid 15010] Worker Worker(salt=2126234251, workers=1, host=LAPTOP-2FUAA63D, username=root, pid=15010) running   LoadData()
2025-01-19 06:19:11,879 - INFO - [pid 15010] Worker Worker(salt=2126234251, workers=1, host=LAPTOP-2FUAA63D, username=root, pid=15010) done      LoadData()
2025-01-19 06:19:11,879 - DEBUG - 1 running tasks, waiting for next task to finish
2025-01-19 06:19:11,882 - INFO - Informed scheduler that task   LoadData__99914b932b   has status   DONE
2025-01-19 06:19:11,882 - DEBUG - Asking scheduler for work...
2025-01-19 06:19:11,884 - DEBUG - Done
2025-01-19 06:19:11,884 - DEBUG - There are no more tasks to run at this time
2025-01-19 06:19:11,884 - INFO - Worker Worker(salt=2126234251, workers=1, host=LAPTOP-2FUAA63D, username=root, pid=15010) was stopped. Shutting down Keep-Alive thread
2025-01-19 06:19:11,885 - INFO - 
===== Luigi Execution Summary =====

Scheduled 8 tasks of which:
* 8 ran successfully:
    - 1 ExtractMarketingData()
    - 1 ExtractNewsData()
    - 1 ExtractSalesData()
    - 1 LoadData()
    - 1 TransformMarketingData()
    ...

This progress looks :) because there were no failed tasks or missing dependencies

===== Luigi Execution Summary =====

2025-01-19 06:49:48,623 - INFO - Worker Worker(salt=3781582697, workers=1, host=LAPTOP-2FUAA63D, username=root, pid=29631) was stopped. Shutting down Keep-Alive thread
2025-01-19 06:51:40,917 - INFO - [pid 31578] Worker Worker(salt=9309487411, workers=1, host=LAPTOP-2FUAA63D, username=root, pid=31578) done      ExtractMarketingData()
2025-01-19 06:51:40,917 - DEBUG - 1 running tasks, waiting for next task to finish
2025-01-19 06:51:40,920 - INFO - Informed scheduler that task   ExtractMarketingData__99914b932b   has status   DONE
2025-01-19 06:51:40,921 - DEBUG - Asking scheduler for work...
2025-01-19 06:51:40,923 - DEBUG - Pending tasks: 7
2025-01-19 06:51:40,923 - INFO - [pid 31578] Worker Worker(salt=9309487411, workers=1, host=LAPTOP-2FUAA63D, username=root, pid=31578) running   ExtractSalesData()
2025-01-19 06:51:42,188 - INFO - [pid 31578] Worker Worker(salt=9309487411, workers=1, host=LAPTOP-2FUAA63D, username=root, pid=31578) done      ExtractSalesData()
2025-01-19 06:51:42,188 - DEBUG - 1 running tasks, waiting for next task to finish
2025-01-19 06:51:42,191 - INFO - Informed scheduler that task   ExtractSalesData__99914b932b   has status   DONE
2025-01-19 06:51:42,191 - DEBUG - Asking scheduler for work...
2025-01-19 06:51:42,193 - DEBUG - Pending tasks: 6
2025-01-19 06:51:42,193 - INFO - [pid 31578] Worker Worker(salt=9309487411, workers=1, host=LAPTOP-2FUAA63D, username=root, pid=31578) running   ExtractNewsData()
2025-01-19 06:53:42,035 - ERROR - [pid 31578] Worker Worker(salt=9309487411, workers=1, host=LAPTOP-2FUAA63D, username=root, pid=31578) failed    ExtractNewsData()
Traceback (most recent call last):
  File "/usr/lib/python3/dist-packages/urllib3/connectionpool.py", line 700, in urlopen
    httplib_response = self._make_request(
  File "/usr/lib/python3/dist-packages/urllib3/connectionpool.py", line 383, in _make_request
    self._validate_conn(conn)
  File "/usr/lib/python3/dist-packages/urllib3/connectionpool.py", line 1017, in _validate_conn
    conn.connect()
  File "/usr/lib/python3/dist-packages/urllib3/connection.py", line 411, in connect
    self.sock = ssl_wrap_socket(
  File "/usr/lib/python3/dist-packages/urllib3/util/ssl_.py", line 449, in ssl_wrap_socket
    ssl_sock = _ssl_wrap_socket_impl(
  File "/usr/lib/python3/dist-packages/urllib3/util/ssl_.py", line 493, in _ssl_wrap_socket_impl
    return ssl_context.wrap_socket(sock, server_hostname=server_hostname)
  File "/usr/lib/python3.10/ssl.py", line 513, in wrap_socket
    return self.sslsocket_class._create(
  File "/usr/lib/python3.10/ssl.py", line 1100, in _create
    self.do_handshake()
  File "/usr/lib/python3.10/ssl.py", line 1371, in do_handshake
    self._sslobj.do_handshake()
ConnectionResetError: [Errno 104] Connection reset by peer

During handling of the above exception, another exception occurred:

Traceback (most recent call last):
  File "/usr/lib/python3/dist-packages/requests/adapters.py", line 439, in send
    resp = conn.urlopen(
  File "/usr/lib/python3/dist-packages/urllib3/connectionpool.py", line 756, in urlopen
    retries = retries.increment(
  File "/usr/lib/python3/dist-packages/urllib3/util/retry.py", line 534, in increment
    raise six.reraise(type(error), error, _stacktrace)
  File "/usr/lib/python3/dist-packages/six.py", line 718, in reraise
    raise value.with_traceback(tb)
  File "/usr/lib/python3/dist-packages/urllib3/connectionpool.py", line 700, in urlopen
    httplib_response = self._make_request(
  File "/usr/lib/python3/dist-packages/urllib3/connectionpool.py", line 383, in _make_request
    self._validate_conn(conn)
  File "/usr/lib/python3/dist-packages/urllib3/connectionpool.py", line 1017, in _validate_conn
    conn.connect()
  File "/usr/lib/python3/dist-packages/urllib3/connection.py", line 411, in connect
    self.sock = ssl_wrap_socket(
  File "/usr/lib/python3/dist-packages/urllib3/util/ssl_.py", line 449, in ssl_wrap_socket
    ssl_sock = _ssl_wrap_socket_impl(
  File "/usr/lib/python3/dist-packages/urllib3/util/ssl_.py", line 493, in _ssl_wrap_socket_impl
    return ssl_context.wrap_socket(sock, server_hostname=server_hostname)
  File "/usr/lib/python3.10/ssl.py", line 513, in wrap_socket
    return self.sslsocket_class._create(
  File "/usr/lib/python3.10/ssl.py", line 1100, in _create
    self.do_handshake()
  File "/usr/lib/python3.10/ssl.py", line 1371, in do_handshake
    self._sslobj.do_handshake()
urllib3.exceptions.ProtocolError: ('Connection aborted.', ConnectionResetError(104, 'Connection reset by peer'))

During handling of the above exception, another exception occurred:

Traceback (most recent call last):
  File "/root/etl_final_task/etl_luigi.py", line 287, in run
    resp2 = requests.get(get_link)
  File "/usr/lib/python3/dist-packages/requests/api.py", line 76, in get
    return request('get', url, params=params, **kwargs)
  File "/usr/lib/python3/dist-packages/requests/api.py", line 61, in request
    return session.request(method=method, url=url, **kwargs)
  File "/usr/lib/python3/dist-packages/requests/sessions.py", line 544, in request
    resp = self.send(prep, **send_kwargs)
  File "/usr/lib/python3/dist-packages/requests/sessions.py", line 657, in send
    r = adapter.send(request, **kwargs)
  File "/usr/lib/python3/dist-packages/requests/adapters.py", line 498, in send
    raise ConnectionError(err, request=request)
requests.exceptions.ConnectionError: ('Connection aborted.', ConnectionResetError(104, 'Connection reset by peer'))

During handling of the above exception, another exception occurred:

Traceback (most recent call last):
  File "/usr/local/lib/python3.10/dist-packages/luigi/worker.py", line 210, in run
    new_deps = self._run_get_new_deps()
  File "/usr/local/lib/python3.10/dist-packages/luigi/worker.py", line 138, in _run_get_new_deps
    task_gen = self.task.run()
  File "/root/etl_final_task/etl_luigi.py", line 338, in run
    raise Exception(f"There's some error: {e}")
Exception: There's some error: ('Connection aborted.', ConnectionResetError(104, 'Connection reset by peer'))
2025-01-19 06:53:42,043 - DEBUG - 1 running tasks, waiting for next task to finish
2025-01-19 06:53:42,052 - INFO - Informed scheduler that task   ExtractNewsData__99914b932b   has status   FAILED
2025-01-19 06:53:42,052 - DEBUG - Asking scheduler for work...
2025-01-19 06:53:42,055 - DEBUG - Pending tasks: 6
2025-01-19 06:53:42,055 - INFO - [pid 31578] Worker Worker(salt=9309487411, workers=1, host=LAPTOP-2FUAA63D, username=root, pid=31578) running   TransformMarketingData()
2025-01-19 06:53:45,958 - INFO - [pid 31578] Worker Worker(salt=9309487411, workers=1, host=LAPTOP-2FUAA63D, username=root, pid=31578) done      TransformMarketingData()
2025-01-19 06:53:45,959 - DEBUG - 1 running tasks, waiting for next task to finish
2025-01-19 06:53:45,961 - INFO - Informed scheduler that task   TransformMarketingData__99914b932b   has status   DONE
2025-01-19 06:53:45,962 - DEBUG - Asking scheduler for work...
2025-01-19 06:53:45,964 - DEBUG - Pending tasks: 5
2025-01-19 06:53:45,964 - INFO - [pid 31578] Worker Worker(salt=9309487411, workers=1, host=LAPTOP-2FUAA63D, username=root, pid=31578) running   TransformSalesData()
2025-01-19 06:53:47,310 - INFO - [pid 31578] Worker Worker(salt=9309487411, workers=1, host=LAPTOP-2FUAA63D, username=root, pid=31578) done      TransformSalesData()
2025-01-19 06:53:47,311 - DEBUG - 1 running tasks, waiting for next task to finish
2025-01-19 06:53:47,314 - INFO - Informed scheduler that task   TransformSalesData__99914b932b   has status   DONE
2025-01-19 06:53:47,314 - DEBUG - Asking scheduler for work...
2025-01-19 06:53:47,317 - DEBUG - Done
2025-01-19 06:53:47,317 - DEBUG - There are no more tasks to run at this time
2025-01-19 06:53:47,317 - DEBUG - There are 4 pending tasks possibly being run by other workers
2025-01-19 06:53:47,317 - DEBUG - There are 4 pending tasks unique to this worker
2025-01-19 06:53:47,317 - DEBUG - There are 4 pending tasks last scheduled by this worker
2025-01-19 06:53:47,317 - INFO - Worker Worker(salt=9309487411, workers=1, host=LAPTOP-2FUAA63D, username=root, pid=31578) was stopped. Shutting down Keep-Alive thread
2025-01-19 06:53:47,319 - INFO - 
===== Luigi Execution Summary =====

Scheduled 8 tasks of which:
* 4 ran successfully:
    - 1 ExtractMarketingData()
    - 1 ExtractSalesData()
    - 1 TransformMarketingData()
    - 1 TransformSalesData()
* 1 failed:
    - 1 ExtractNewsData()
* 3 were left pending, among these:
    * 3 had failed dependencies:
        - 1 LoadData()
        - 1 TransformNewsData()
        - 1 ValidateData()

This progress looks :( because there were failed tasks

===== Luigi Execution Summary =====

2025-01-19 17:12:20,796 - INFO - [pid 2402] Worker Worker(salt=3693378965, workers=1, host=LAPTOP-2FUAA63D, username=root, pid=2402) done      ExtractMarketingData()
2025-01-19 17:12:20,798 - DEBUG - 1 running tasks, waiting for next task to finish
2025-01-19 17:12:20,801 - INFO - Informed scheduler that task   ExtractMarketingData__99914b932b   has status   DONE
2025-01-19 17:12:20,801 - DEBUG - Asking scheduler for work...
2025-01-19 17:12:20,803 - DEBUG - Pending tasks: 7
2025-01-19 17:12:20,803 - INFO - [pid 2402] Worker Worker(salt=3693378965, workers=1, host=LAPTOP-2FUAA63D, username=root, pid=2402) running   ExtractSalesData()
2025-01-19 17:12:22,206 - INFO - [pid 2402] Worker Worker(salt=3693378965, workers=1, host=LAPTOP-2FUAA63D, username=root, pid=2402) done      ExtractSalesData()
2025-01-19 17:12:22,207 - DEBUG - 1 running tasks, waiting for next task to finish
2025-01-19 17:12:22,210 - INFO - Informed scheduler that task   ExtractSalesData__99914b932b   has status   DONE
2025-01-19 17:12:22,210 - DEBUG - Asking scheduler for work...
2025-01-19 17:12:22,212 - DEBUG - Pending tasks: 6
2025-01-19 17:12:22,212 - INFO - [pid 2402] Worker Worker(salt=3693378965, workers=1, host=LAPTOP-2FUAA63D, username=root, pid=2402) running   ExtractNewsData()
2025-01-19 17:15:39,626 - ERROR - [pid 2402] Worker Worker(salt=3693378965, workers=1, host=LAPTOP-2FUAA63D, username=root, pid=2402) failed    ExtractNewsData()
Traceback (most recent call last):
  File "/usr/lib/python3/dist-packages/urllib3/connectionpool.py", line 700, in urlopen
    httplib_response = self._make_request(
  File "/usr/lib/python3/dist-packages/urllib3/connectionpool.py", line 383, in _make_request
    self._validate_conn(conn)
  File "/usr/lib/python3/dist-packages/urllib3/connectionpool.py", line 1017, in _validate_conn
    conn.connect()
  File "/usr/lib/python3/dist-packages/urllib3/connection.py", line 411, in connect
    self.sock = ssl_wrap_socket(
  File "/usr/lib/python3/dist-packages/urllib3/util/ssl_.py", line 449, in ssl_wrap_socket
    ssl_sock = _ssl_wrap_socket_impl(
  File "/usr/lib/python3/dist-packages/urllib3/util/ssl_.py", line 493, in _ssl_wrap_socket_impl
    return ssl_context.wrap_socket(sock, server_hostname=server_hostname)
  File "/usr/lib/python3.10/ssl.py", line 513, in wrap_socket
    return self.sslsocket_class._create(
  File "/usr/lib/python3.10/ssl.py", line 1100, in _create
    self.do_handshake()
  File "/usr/lib/python3.10/ssl.py", line 1371, in do_handshake
    self._sslobj.do_handshake()
ConnectionResetError: [Errno 104] Connection reset by peer

During handling of the above exception, another exception occurred:

Traceback (most recent call last):
  File "/usr/lib/python3/dist-packages/requests/adapters.py", line 439, in send
    resp = conn.urlopen(
  File "/usr/lib/python3/dist-packages/urllib3/connectionpool.py", line 756, in urlopen
    retries = retries.increment(
  File "/usr/lib/python3/dist-packages/urllib3/util/retry.py", line 534, in increment
    raise six.reraise(type(error), error, _stacktrace)
  File "/usr/lib/python3/dist-packages/six.py", line 718, in reraise
    raise value.with_traceback(tb)
  File "/usr/lib/python3/dist-packages/urllib3/connectionpool.py", line 700, in urlopen
    httplib_response = self._make_request(
  File "/usr/lib/python3/dist-packages/urllib3/connectionpool.py", line 383, in _make_request
    self._validate_conn(conn)
  File "/usr/lib/python3/dist-packages/urllib3/connectionpool.py", line 1017, in _validate_conn
    conn.connect()
  File "/usr/lib/python3/dist-packages/urllib3/connection.py", line 411, in connect
    self.sock = ssl_wrap_socket(
  File "/usr/lib/python3/dist-packages/urllib3/util/ssl_.py", line 449, in ssl_wrap_socket
    ssl_sock = _ssl_wrap_socket_impl(
  File "/usr/lib/python3/dist-packages/urllib3/util/ssl_.py", line 493, in _ssl_wrap_socket_impl
    return ssl_context.wrap_socket(sock, server_hostname=server_hostname)
  File "/usr/lib/python3.10/ssl.py", line 513, in wrap_socket
    return self.sslsocket_class._create(
  File "/usr/lib/python3.10/ssl.py", line 1100, in _create
    self.do_handshake()
  File "/usr/lib/python3.10/ssl.py", line 1371, in do_handshake
    self._sslobj.do_handshake()
urllib3.exceptions.ProtocolError: ('Connection aborted.', ConnectionResetError(104, 'Connection reset by peer'))

During handling of the above exception, another exception occurred:

Traceback (most recent call last):
  File "/root/etl_final_task/etl_luigi.py", line 287, in run
    resp2 = requests.get(get_link)
  File "/usr/lib/python3/dist-packages/requests/api.py", line 76, in get
    return request('get', url, params=params, **kwargs)
  File "/usr/lib/python3/dist-packages/requests/api.py", line 61, in request
    return session.request(method=method, url=url, **kwargs)
  File "/usr/lib/python3/dist-packages/requests/sessions.py", line 544, in request
    resp = self.send(prep, **send_kwargs)
  File "/usr/lib/python3/dist-packages/requests/sessions.py", line 657, in send
    r = adapter.send(request, **kwargs)
  File "/usr/lib/python3/dist-packages/requests/adapters.py", line 498, in send
    raise ConnectionError(err, request=request)
requests.exceptions.ConnectionError: ('Connection aborted.', ConnectionResetError(104, 'Connection reset by peer'))

During handling of the above exception, another exception occurred:

Traceback (most recent call last):
  File "/usr/local/lib/python3.10/dist-packages/luigi/worker.py", line 210, in run
    new_deps = self._run_get_new_deps()
  File "/usr/local/lib/python3.10/dist-packages/luigi/worker.py", line 138, in _run_get_new_deps
    task_gen = self.task.run()
  File "/root/etl_final_task/etl_luigi.py", line 338, in run
    raise Exception(f"There's some error: {e}")
Exception: There's some error: ('Connection aborted.', ConnectionResetError(104, 'Connection reset by peer'))
2025-01-19 17:15:39,635 - DEBUG - 1 running tasks, waiting for next task to finish
2025-01-19 17:15:39,641 - INFO - Informed scheduler that task   ExtractNewsData__99914b932b   has status   FAILED
2025-01-19 17:15:39,641 - DEBUG - Asking scheduler for work...
2025-01-19 17:15:39,643 - DEBUG - Pending tasks: 6
2025-01-19 17:15:39,643 - INFO - [pid 2402] Worker Worker(salt=3693378965, workers=1, host=LAPTOP-2FUAA63D, username=root, pid=2402) running   TransformMarketingData()
2025-01-19 17:15:43,680 - INFO - [pid 2402] Worker Worker(salt=3693378965, workers=1, host=LAPTOP-2FUAA63D, username=root, pid=2402) done      TransformMarketingData()
2025-01-19 17:15:43,680 - DEBUG - 1 running tasks, waiting for next task to finish
2025-01-19 17:15:43,683 - INFO - Informed scheduler that task   TransformMarketingData__99914b932b   has status   DONE
2025-01-19 17:15:43,683 - DEBUG - Asking scheduler for work...
2025-01-19 17:15:43,685 - DEBUG - Pending tasks: 5
2025-01-19 17:15:43,685 - INFO - [pid 2402] Worker Worker(salt=3693378965, workers=1, host=LAPTOP-2FUAA63D, username=root, pid=2402) running   TransformSalesData()
2025-01-19 17:15:44,968 - INFO - [pid 2402] Worker Worker(salt=3693378965, workers=1, host=LAPTOP-2FUAA63D, username=root, pid=2402) done      TransformSalesData()
2025-01-19 17:15:44,969 - DEBUG - 1 running tasks, waiting for next task to finish
2025-01-19 17:15:44,971 - INFO - Informed scheduler that task   TransformSalesData__99914b932b   has status   DONE
2025-01-19 17:15:44,972 - DEBUG - Asking scheduler for work...
2025-01-19 17:15:44,973 - DEBUG - Done
2025-01-19 17:15:44,974 - DEBUG - There are no more tasks to run at this time
2025-01-19 17:15:44,974 - DEBUG - There are 4 pending tasks possibly being run by other workers
2025-01-19 17:15:44,974 - DEBUG - There are 4 pending tasks unique to this worker
2025-01-19 17:15:44,974 - DEBUG - There are 4 pending tasks last scheduled by this worker
2025-01-19 17:15:44,974 - INFO - Worker Worker(salt=3693378965, workers=1, host=LAPTOP-2FUAA63D, username=root, pid=2402) was stopped. Shutting down Keep-Alive thread
2025-01-19 17:15:44,975 - INFO - 
===== Luigi Execution Summary =====

Scheduled 8 tasks of which:
* 4 ran successfully:
    - 1 ExtractMarketingData()
    - 1 ExtractSalesData()
    - 1 TransformMarketingData()
    - 1 TransformSalesData()
* 1 failed:
    - 1 ExtractNewsData()
* 3 were left pending, among these:
    * 3 had failed dependencies:
        - 1 LoadData()
        - 1 TransformNewsData()
        - 1 ValidateData()

This progress looks :( because there were failed tasks

===== Luigi Execution Summary =====

2025-01-19 17:16:36,298 - INFO - [pid 4386] Worker Worker(salt=9846528137, workers=1, host=LAPTOP-2FUAA63D, username=root, pid=4386) done      ExtractMarketingData()
2025-01-19 17:16:36,299 - DEBUG - 1 running tasks, waiting for next task to finish
2025-01-19 17:16:36,302 - INFO - Informed scheduler that task   ExtractMarketingData__99914b932b   has status   DONE
2025-01-19 17:16:36,302 - DEBUG - Asking scheduler for work...
2025-01-19 17:16:36,304 - DEBUG - Pending tasks: 7
2025-01-19 17:16:36,304 - INFO - [pid 4386] Worker Worker(salt=9846528137, workers=1, host=LAPTOP-2FUAA63D, username=root, pid=4386) running   ExtractSalesData()
2025-01-19 17:16:37,465 - INFO - [pid 4386] Worker Worker(salt=9846528137, workers=1, host=LAPTOP-2FUAA63D, username=root, pid=4386) done      ExtractSalesData()
2025-01-19 17:16:37,466 - DEBUG - 1 running tasks, waiting for next task to finish
2025-01-19 17:16:37,469 - INFO - Informed scheduler that task   ExtractSalesData__99914b932b   has status   DONE
2025-01-19 17:16:37,469 - DEBUG - Asking scheduler for work...
2025-01-19 17:16:37,471 - DEBUG - Pending tasks: 6
2025-01-19 17:16:37,471 - INFO - [pid 4386] Worker Worker(salt=9846528137, workers=1, host=LAPTOP-2FUAA63D, username=root, pid=4386) running   ExtractNewsData()
2025-01-19 17:20:31,535 - ERROR - [pid 4386] Worker Worker(salt=9846528137, workers=1, host=LAPTOP-2FUAA63D, username=root, pid=4386) failed    ExtractNewsData()
Traceback (most recent call last):
  File "/usr/lib/python3/dist-packages/urllib3/connectionpool.py", line 700, in urlopen
    httplib_response = self._make_request(
  File "/usr/lib/python3/dist-packages/urllib3/connectionpool.py", line 383, in _make_request
    self._validate_conn(conn)
  File "/usr/lib/python3/dist-packages/urllib3/connectionpool.py", line 1017, in _validate_conn
    conn.connect()
  File "/usr/lib/python3/dist-packages/urllib3/connection.py", line 411, in connect
    self.sock = ssl_wrap_socket(
  File "/usr/lib/python3/dist-packages/urllib3/util/ssl_.py", line 449, in ssl_wrap_socket
    ssl_sock = _ssl_wrap_socket_impl(
  File "/usr/lib/python3/dist-packages/urllib3/util/ssl_.py", line 493, in _ssl_wrap_socket_impl
    return ssl_context.wrap_socket(sock, server_hostname=server_hostname)
  File "/usr/lib/python3.10/ssl.py", line 513, in wrap_socket
    return self.sslsocket_class._create(
  File "/usr/lib/python3.10/ssl.py", line 1100, in _create
    self.do_handshake()
  File "/usr/lib/python3.10/ssl.py", line 1371, in do_handshake
    self._sslobj.do_handshake()
ConnectionResetError: [Errno 104] Connection reset by peer

During handling of the above exception, another exception occurred:

Traceback (most recent call last):
  File "/usr/lib/python3/dist-packages/requests/adapters.py", line 439, in send
    resp = conn.urlopen(
  File "/usr/lib/python3/dist-packages/urllib3/connectionpool.py", line 756, in urlopen
    retries = retries.increment(
  File "/usr/lib/python3/dist-packages/urllib3/util/retry.py", line 534, in increment
    raise six.reraise(type(error), error, _stacktrace)
  File "/usr/lib/python3/dist-packages/six.py", line 718, in reraise
    raise value.with_traceback(tb)
  File "/usr/lib/python3/dist-packages/urllib3/connectionpool.py", line 700, in urlopen
    httplib_response = self._make_request(
  File "/usr/lib/python3/dist-packages/urllib3/connectionpool.py", line 383, in _make_request
    self._validate_conn(conn)
  File "/usr/lib/python3/dist-packages/urllib3/connectionpool.py", line 1017, in _validate_conn
    conn.connect()
  File "/usr/lib/python3/dist-packages/urllib3/connection.py", line 411, in connect
    self.sock = ssl_wrap_socket(
  File "/usr/lib/python3/dist-packages/urllib3/util/ssl_.py", line 449, in ssl_wrap_socket
    ssl_sock = _ssl_wrap_socket_impl(
  File "/usr/lib/python3/dist-packages/urllib3/util/ssl_.py", line 493, in _ssl_wrap_socket_impl
    return ssl_context.wrap_socket(sock, server_hostname=server_hostname)
  File "/usr/lib/python3.10/ssl.py", line 513, in wrap_socket
    return self.sslsocket_class._create(
  File "/usr/lib/python3.10/ssl.py", line 1100, in _create
    self.do_handshake()
  File "/usr/lib/python3.10/ssl.py", line 1371, in do_handshake
    self._sslobj.do_handshake()
urllib3.exceptions.ProtocolError: ('Connection aborted.', ConnectionResetError(104, 'Connection reset by peer'))

During handling of the above exception, another exception occurred:

Traceback (most recent call last):
  File "/root/etl_final_task/etl_luigi.py", line 287, in run
    resp2 = requests.get(get_link)
  File "/usr/lib/python3/dist-packages/requests/api.py", line 76, in get
    return request('get', url, params=params, **kwargs)
  File "/usr/lib/python3/dist-packages/requests/api.py", line 61, in request
    return session.request(method=method, url=url, **kwargs)
  File "/usr/lib/python3/dist-packages/requests/sessions.py", line 544, in request
    resp = self.send(prep, **send_kwargs)
  File "/usr/lib/python3/dist-packages/requests/sessions.py", line 657, in send
    r = adapter.send(request, **kwargs)
  File "/usr/lib/python3/dist-packages/requests/adapters.py", line 498, in send
    raise ConnectionError(err, request=request)
requests.exceptions.ConnectionError: ('Connection aborted.', ConnectionResetError(104, 'Connection reset by peer'))

During handling of the above exception, another exception occurred:

Traceback (most recent call last):
  File "/usr/local/lib/python3.10/dist-packages/luigi/worker.py", line 210, in run
    new_deps = self._run_get_new_deps()
  File "/usr/local/lib/python3.10/dist-packages/luigi/worker.py", line 138, in _run_get_new_deps
    task_gen = self.task.run()
  File "/root/etl_final_task/etl_luigi.py", line 338, in run
    raise Exception(f"There's some error: {e}")
Exception: There's some error: ('Connection aborted.', ConnectionResetError(104, 'Connection reset by peer'))
2025-01-19 17:20:31,538 - DEBUG - 1 running tasks, waiting for next task to finish
2025-01-19 17:20:31,544 - INFO - Informed scheduler that task   ExtractNewsData__99914b932b   has status   FAILED
2025-01-19 17:20:31,544 - DEBUG - Asking scheduler for work...
2025-01-19 17:20:31,548 - DEBUG - Pending tasks: 6
2025-01-19 17:20:31,548 - INFO - [pid 4386] Worker Worker(salt=9846528137, workers=1, host=LAPTOP-2FUAA63D, username=root, pid=4386) running   TransformMarketingData()
2025-01-19 17:20:35,534 - INFO - [pid 4386] Worker Worker(salt=9846528137, workers=1, host=LAPTOP-2FUAA63D, username=root, pid=4386) done      TransformMarketingData()
2025-01-19 17:20:35,534 - DEBUG - 1 running tasks, waiting for next task to finish
2025-01-19 17:20:35,537 - INFO - Informed scheduler that task   TransformMarketingData__99914b932b   has status   DONE
2025-01-19 17:20:35,537 - DEBUG - Asking scheduler for work...
2025-01-19 17:20:35,540 - DEBUG - Pending tasks: 5
2025-01-19 17:20:35,540 - INFO - [pid 4386] Worker Worker(salt=9846528137, workers=1, host=LAPTOP-2FUAA63D, username=root, pid=4386) running   TransformSalesData()
2025-01-19 17:20:36,943 - INFO - [pid 4386] Worker Worker(salt=9846528137, workers=1, host=LAPTOP-2FUAA63D, username=root, pid=4386) done      TransformSalesData()
2025-01-19 17:20:36,944 - DEBUG - 1 running tasks, waiting for next task to finish
2025-01-19 17:20:36,947 - INFO - Informed scheduler that task   TransformSalesData__99914b932b   has status   DONE
2025-01-19 17:20:36,947 - DEBUG - Asking scheduler for work...
2025-01-19 17:20:36,949 - DEBUG - Done
2025-01-19 17:20:36,949 - DEBUG - There are no more tasks to run at this time
2025-01-19 17:20:36,949 - DEBUG - There are 4 pending tasks possibly being run by other workers
2025-01-19 17:20:36,949 - DEBUG - There are 4 pending tasks unique to this worker
2025-01-19 17:20:36,949 - DEBUG - There are 4 pending tasks last scheduled by this worker
2025-01-19 17:20:36,949 - INFO - Worker Worker(salt=9846528137, workers=1, host=LAPTOP-2FUAA63D, username=root, pid=4386) was stopped. Shutting down Keep-Alive thread
2025-01-19 17:20:36,951 - INFO - 
===== Luigi Execution Summary =====

Scheduled 8 tasks of which:
* 4 ran successfully:
    - 1 ExtractMarketingData()
    - 1 ExtractSalesData()
    - 1 TransformMarketingData()
    - 1 TransformSalesData()
* 1 failed:
    - 1 ExtractNewsData()
* 3 were left pending, among these:
    * 3 had failed dependencies:
        - 1 LoadData()
        - 1 TransformNewsData()
        - 1 ValidateData()

This progress looks :( because there were failed tasks

===== Luigi Execution Summary =====

2025-01-19 17:25:11,131 - INFO - [pid 8492] Worker Worker(salt=3190889801, workers=1, host=LAPTOP-2FUAA63D, username=root, pid=8492) done      ExtractMarketingData()
2025-01-19 17:25:11,132 - DEBUG - 1 running tasks, waiting for next task to finish
2025-01-19 17:25:11,134 - INFO - Informed scheduler that task   ExtractMarketingData__99914b932b   has status   DONE
2025-01-19 17:25:11,134 - DEBUG - Asking scheduler for work...
2025-01-19 17:25:11,136 - DEBUG - Pending tasks: 7
2025-01-19 17:25:11,136 - INFO - [pid 8492] Worker Worker(salt=3190889801, workers=1, host=LAPTOP-2FUAA63D, username=root, pid=8492) running   ExtractSalesData()
2025-01-19 17:25:12,333 - INFO - [pid 8492] Worker Worker(salt=3190889801, workers=1, host=LAPTOP-2FUAA63D, username=root, pid=8492) done      ExtractSalesData()
2025-01-19 17:25:12,333 - DEBUG - 1 running tasks, waiting for next task to finish
2025-01-19 17:25:12,337 - INFO - Informed scheduler that task   ExtractSalesData__99914b932b   has status   DONE
2025-01-19 17:25:12,337 - DEBUG - Asking scheduler for work...
2025-01-19 17:25:12,339 - DEBUG - Pending tasks: 6
2025-01-19 17:25:12,339 - INFO - [pid 8492] Worker Worker(salt=3190889801, workers=1, host=LAPTOP-2FUAA63D, username=root, pid=8492) running   ExtractNewsData()
2025-01-19 17:27:10,798 - ERROR - [pid 8492] Worker Worker(salt=3190889801, workers=1, host=LAPTOP-2FUAA63D, username=root, pid=8492) failed    ExtractNewsData()
Traceback (most recent call last):
  File "/usr/lib/python3/dist-packages/urllib3/connectionpool.py", line 700, in urlopen
    httplib_response = self._make_request(
  File "/usr/lib/python3/dist-packages/urllib3/connectionpool.py", line 383, in _make_request
    self._validate_conn(conn)
  File "/usr/lib/python3/dist-packages/urllib3/connectionpool.py", line 1017, in _validate_conn
    conn.connect()
  File "/usr/lib/python3/dist-packages/urllib3/connection.py", line 411, in connect
    self.sock = ssl_wrap_socket(
  File "/usr/lib/python3/dist-packages/urllib3/util/ssl_.py", line 449, in ssl_wrap_socket
    ssl_sock = _ssl_wrap_socket_impl(
  File "/usr/lib/python3/dist-packages/urllib3/util/ssl_.py", line 493, in _ssl_wrap_socket_impl
    return ssl_context.wrap_socket(sock, server_hostname=server_hostname)
  File "/usr/lib/python3.10/ssl.py", line 513, in wrap_socket
    return self.sslsocket_class._create(
  File "/usr/lib/python3.10/ssl.py", line 1100, in _create
    self.do_handshake()
  File "/usr/lib/python3.10/ssl.py", line 1371, in do_handshake
    self._sslobj.do_handshake()
ConnectionResetError: [Errno 104] Connection reset by peer

During handling of the above exception, another exception occurred:

Traceback (most recent call last):
  File "/usr/lib/python3/dist-packages/requests/adapters.py", line 439, in send
    resp = conn.urlopen(
  File "/usr/lib/python3/dist-packages/urllib3/connectionpool.py", line 756, in urlopen
    retries = retries.increment(
  File "/usr/lib/python3/dist-packages/urllib3/util/retry.py", line 534, in increment
    raise six.reraise(type(error), error, _stacktrace)
  File "/usr/lib/python3/dist-packages/six.py", line 718, in reraise
    raise value.with_traceback(tb)
  File "/usr/lib/python3/dist-packages/urllib3/connectionpool.py", line 700, in urlopen
    httplib_response = self._make_request(
  File "/usr/lib/python3/dist-packages/urllib3/connectionpool.py", line 383, in _make_request
    self._validate_conn(conn)
  File "/usr/lib/python3/dist-packages/urllib3/connectionpool.py", line 1017, in _validate_conn
    conn.connect()
  File "/usr/lib/python3/dist-packages/urllib3/connection.py", line 411, in connect
    self.sock = ssl_wrap_socket(
  File "/usr/lib/python3/dist-packages/urllib3/util/ssl_.py", line 449, in ssl_wrap_socket
    ssl_sock = _ssl_wrap_socket_impl(
  File "/usr/lib/python3/dist-packages/urllib3/util/ssl_.py", line 493, in _ssl_wrap_socket_impl
    return ssl_context.wrap_socket(sock, server_hostname=server_hostname)
  File "/usr/lib/python3.10/ssl.py", line 513, in wrap_socket
    return self.sslsocket_class._create(
  File "/usr/lib/python3.10/ssl.py", line 1100, in _create
    self.do_handshake()
  File "/usr/lib/python3.10/ssl.py", line 1371, in do_handshake
    self._sslobj.do_handshake()
urllib3.exceptions.ProtocolError: ('Connection aborted.', ConnectionResetError(104, 'Connection reset by peer'))

During handling of the above exception, another exception occurred:

Traceback (most recent call last):
  File "/usr/local/lib/python3.10/dist-packages/luigi/worker.py", line 210, in run
    new_deps = self._run_get_new_deps()
  File "/usr/local/lib/python3.10/dist-packages/luigi/worker.py", line 138, in _run_get_new_deps
    task_gen = self.task.run()
  File "/root/etl_final_task/etl_luigi.py", line 253, in run
    resp = requests.get(f"{url}/2?page={page}")
  File "/usr/lib/python3/dist-packages/requests/api.py", line 76, in get
    return request('get', url, params=params, **kwargs)
  File "/usr/lib/python3/dist-packages/requests/api.py", line 61, in request
    return session.request(method=method, url=url, **kwargs)
  File "/usr/lib/python3/dist-packages/requests/sessions.py", line 544, in request
    resp = self.send(prep, **send_kwargs)
  File "/usr/lib/python3/dist-packages/requests/sessions.py", line 657, in send
    r = adapter.send(request, **kwargs)
  File "/usr/lib/python3/dist-packages/requests/adapters.py", line 498, in send
    raise ConnectionError(err, request=request)
requests.exceptions.ConnectionError: ('Connection aborted.', ConnectionResetError(104, 'Connection reset by peer'))
2025-01-19 17:27:10,801 - DEBUG - 1 running tasks, waiting for next task to finish
2025-01-19 17:27:10,805 - INFO - Informed scheduler that task   ExtractNewsData__99914b932b   has status   FAILED
2025-01-19 17:27:10,806 - DEBUG - Asking scheduler for work...
2025-01-19 17:27:10,807 - DEBUG - Pending tasks: 6
2025-01-19 17:27:10,808 - INFO - [pid 8492] Worker Worker(salt=3190889801, workers=1, host=LAPTOP-2FUAA63D, username=root, pid=8492) running   TransformMarketingData()
2025-01-19 17:27:14,751 - INFO - [pid 8492] Worker Worker(salt=3190889801, workers=1, host=LAPTOP-2FUAA63D, username=root, pid=8492) done      TransformMarketingData()
2025-01-19 17:27:14,752 - DEBUG - 1 running tasks, waiting for next task to finish
2025-01-19 17:27:14,757 - INFO - Informed scheduler that task   TransformMarketingData__99914b932b   has status   DONE
2025-01-19 17:27:14,757 - DEBUG - Asking scheduler for work...
2025-01-19 17:27:14,759 - DEBUG - Pending tasks: 5
2025-01-19 17:27:14,760 - INFO - [pid 8492] Worker Worker(salt=3190889801, workers=1, host=LAPTOP-2FUAA63D, username=root, pid=8492) running   TransformSalesData()
2025-01-19 17:27:16,099 - INFO - [pid 8492] Worker Worker(salt=3190889801, workers=1, host=LAPTOP-2FUAA63D, username=root, pid=8492) done      TransformSalesData()
2025-01-19 17:27:16,100 - DEBUG - 1 running tasks, waiting for next task to finish
2025-01-19 17:27:16,102 - INFO - Informed scheduler that task   TransformSalesData__99914b932b   has status   DONE
2025-01-19 17:27:16,102 - DEBUG - Asking scheduler for work...
2025-01-19 17:27:16,104 - DEBUG - Done
2025-01-19 17:27:16,104 - DEBUG - There are no more tasks to run at this time
2025-01-19 17:27:16,104 - DEBUG - There are 4 pending tasks possibly being run by other workers
2025-01-19 17:27:16,104 - DEBUG - There are 4 pending tasks unique to this worker
2025-01-19 17:27:16,104 - DEBUG - There are 4 pending tasks last scheduled by this worker
2025-01-19 17:27:16,105 - INFO - Worker Worker(salt=3190889801, workers=1, host=LAPTOP-2FUAA63D, username=root, pid=8492) was stopped. Shutting down Keep-Alive thread
2025-01-19 17:27:16,106 - INFO - 
===== Luigi Execution Summary =====

Scheduled 8 tasks of which:
* 4 ran successfully:
    - 1 ExtractMarketingData()
    - 1 ExtractSalesData()
    - 1 TransformMarketingData()
    - 1 TransformSalesData()
* 1 failed:
    - 1 ExtractNewsData()
* 3 were left pending, among these:
    * 3 had failed dependencies:
        - 1 LoadData()
        - 1 TransformNewsData()
        - 1 ValidateData()

This progress looks :( because there were failed tasks

===== Luigi Execution Summary =====

2025-01-19 17:37:38,788 - INFO - [pid 13757] Worker Worker(salt=9338291834, workers=1, host=LAPTOP-2FUAA63D, username=root, pid=13757) done      ExtractMarketingData()
2025-01-19 17:37:38,790 - DEBUG - 1 running tasks, waiting for next task to finish
2025-01-19 17:37:38,793 - INFO - Informed scheduler that task   ExtractMarketingData__99914b932b   has status   DONE
2025-01-19 17:37:38,793 - DEBUG - Asking scheduler for work...
2025-01-19 17:37:38,795 - DEBUG - Pending tasks: 7
2025-01-19 17:37:38,795 - INFO - [pid 13757] Worker Worker(salt=9338291834, workers=1, host=LAPTOP-2FUAA63D, username=root, pid=13757) running   ExtractSalesData()
2025-01-19 17:37:40,013 - INFO - [pid 13757] Worker Worker(salt=9338291834, workers=1, host=LAPTOP-2FUAA63D, username=root, pid=13757) done      ExtractSalesData()
2025-01-19 17:37:40,013 - DEBUG - 1 running tasks, waiting for next task to finish
2025-01-19 17:37:40,016 - INFO - Informed scheduler that task   ExtractSalesData__99914b932b   has status   DONE
2025-01-19 17:37:40,016 - DEBUG - Asking scheduler for work...
2025-01-19 17:37:40,018 - DEBUG - Pending tasks: 6
2025-01-19 17:37:40,018 - INFO - [pid 13757] Worker Worker(salt=9338291834, workers=1, host=LAPTOP-2FUAA63D, username=root, pid=13757) running   ExtractNewsData()
2025-01-19 17:41:03,496 - INFO - [pid 13757] Worker Worker(salt=9338291834, workers=1, host=LAPTOP-2FUAA63D, username=root, pid=13757) done      ExtractNewsData()
2025-01-19 17:41:03,497 - DEBUG - 1 running tasks, waiting for next task to finish
2025-01-19 17:41:03,499 - INFO - Informed scheduler that task   ExtractNewsData__99914b932b   has status   DONE
2025-01-19 17:41:03,500 - DEBUG - Asking scheduler for work...
2025-01-19 17:41:03,502 - DEBUG - Pending tasks: 5
2025-01-19 17:41:03,502 - INFO - [pid 13757] Worker Worker(salt=9338291834, workers=1, host=LAPTOP-2FUAA63D, username=root, pid=13757) running   ValidateData()
2025-01-19 17:41:04,481 - INFO - [pid 13757] Worker Worker(salt=9338291834, workers=1, host=LAPTOP-2FUAA63D, username=root, pid=13757) done      ValidateData()
2025-01-19 17:41:04,481 - DEBUG - 1 running tasks, waiting for next task to finish
2025-01-19 17:41:04,484 - INFO - Informed scheduler that task   ValidateData__99914b932b   has status   DONE
2025-01-19 17:41:04,484 - DEBUG - Asking scheduler for work...
2025-01-19 17:41:04,486 - DEBUG - Pending tasks: 4
2025-01-19 17:41:04,486 - INFO - [pid 13757] Worker Worker(salt=9338291834, workers=1, host=LAPTOP-2FUAA63D, username=root, pid=13757) running   TransformMarketingData()
2025-01-19 17:41:08,422 - INFO - [pid 13757] Worker Worker(salt=9338291834, workers=1, host=LAPTOP-2FUAA63D, username=root, pid=13757) done      TransformMarketingData()
2025-01-19 17:41:08,422 - DEBUG - 1 running tasks, waiting for next task to finish
2025-01-19 17:41:08,425 - INFO - Informed scheduler that task   TransformMarketingData__99914b932b   has status   DONE
2025-01-19 17:41:08,425 - DEBUG - Asking scheduler for work...
2025-01-19 17:41:08,426 - DEBUG - Pending tasks: 3
2025-01-19 17:41:08,427 - INFO - [pid 13757] Worker Worker(salt=9338291834, workers=1, host=LAPTOP-2FUAA63D, username=root, pid=13757) running   TransformSalesData()
2025-01-19 17:41:09,702 - INFO - [pid 13757] Worker Worker(salt=9338291834, workers=1, host=LAPTOP-2FUAA63D, username=root, pid=13757) done      TransformSalesData()
2025-01-19 17:41:09,703 - DEBUG - 1 running tasks, waiting for next task to finish
2025-01-19 17:41:09,705 - INFO - Informed scheduler that task   TransformSalesData__99914b932b   has status   DONE
2025-01-19 17:41:09,706 - DEBUG - Asking scheduler for work...
2025-01-19 17:41:09,708 - DEBUG - Pending tasks: 2
2025-01-19 17:41:09,708 - INFO - [pid 13757] Worker Worker(salt=9338291834, workers=1, host=LAPTOP-2FUAA63D, username=root, pid=13757) running   TransformNewsData()
2025-01-19 17:41:09,718 - INFO - [pid 13757] Worker Worker(salt=9338291834, workers=1, host=LAPTOP-2FUAA63D, username=root, pid=13757) done      TransformNewsData()
2025-01-19 17:41:09,718 - DEBUG - 1 running tasks, waiting for next task to finish
2025-01-19 17:41:09,721 - INFO - Informed scheduler that task   TransformNewsData__99914b932b   has status   DONE
2025-01-19 17:41:09,721 - DEBUG - Asking scheduler for work...
2025-01-19 17:41:09,723 - DEBUG - Pending tasks: 1
2025-01-19 17:41:09,724 - INFO - [pid 13757] Worker Worker(salt=9338291834, workers=1, host=LAPTOP-2FUAA63D, username=root, pid=13757) running   LoadData()
2025-01-19 17:41:11,630 - INFO - [pid 13757] Worker Worker(salt=9338291834, workers=1, host=LAPTOP-2FUAA63D, username=root, pid=13757) done      LoadData()
2025-01-19 17:41:11,631 - DEBUG - 1 running tasks, waiting for next task to finish
2025-01-19 17:41:11,634 - INFO - Informed scheduler that task   LoadData__99914b932b   has status   DONE
2025-01-19 17:41:11,634 - DEBUG - Asking scheduler for work...
2025-01-19 17:41:11,636 - DEBUG - Done
2025-01-19 17:41:11,636 - DEBUG - There are no more tasks to run at this time
2025-01-19 17:41:11,636 - INFO - Worker Worker(salt=9338291834, workers=1, host=LAPTOP-2FUAA63D, username=root, pid=13757) was stopped. Shutting down Keep-Alive thread
2025-01-19 17:41:11,637 - INFO - 
===== Luigi Execution Summary =====

Scheduled 8 tasks of which:
* 8 ran successfully:
    - 1 ExtractMarketingData()
    - 1 ExtractNewsData()
    - 1 ExtractSalesData()
    - 1 LoadData()
    - 1 TransformMarketingData()
    ...

This progress looks :) because there were no failed tasks or missing dependencies

===== Luigi Execution Summary =====

